Workbook

Sheet Monster
A1: id | B1: name | C1: set_prefix | D1: equipment_prefix | E1: #dup_id | G1: id | H1: name | I1: #dup_id
A2: 1 | B2: Great Jagras | C2: Jagras | D2: Jagras | E2: =$A2 -> 1 | G2: 1 | H2: Fire | I2: =G2 -> 1
A3: 2 | B3: Kulu-Ya-Ku | C3: Kulu | D3: Kulu | E3: =$A3 -> 2 | G3: 2 | H3: Water | I3: =G3 -> 2
A4: 3 | B4: Pukei-Pukei | C4: Pukei | D4: Pukei | E4: =$A4 -> 3 | G4: 3 | H4: Thunder | I4: =G4 -> 3
A5: 4 | B5: Coral Pukei-Pukei | C5: Coral Pukei | D5: Pukei Lagoon | E5: =$A5 -> 4 | G5: 4 | H5: Ice | I5: =G5 -> 4
A6: 5 | B6: Barroth | C6: Barroth | D6: Barroth | E6: =$A6 -> 5 | G6: 5 | H6: Dragon | I6: =G6 -> 5
A7: 6 | B7: Great Girros | C7: Girros | D7: Girros | E7: =$A7 -> 6 | G7: 6 | H7: Poison | I7: =G7 -> 6
A8: 7 | B8: Tobi-Kadachi | C8: Kadachi | D8: Kadachi | E8: =$A8 -> 7 | G8: 7 | H8: Paralysis | I8: =G8 -> 7
A9: 8 | B9: Paolumu | C9: Paolumu | D9: Lumu | E9: =$A9 -> 8 | G9: 8 | H9: Sleep | I9: =G9 -> 8
A10: 9 | B10: Nightshade Paolumu | C10: Nightshade Paolumu | D10: Lumu Phantasm | E10: =$A10 -> 9 | G10: 9 | H10: Blast | I10: =G10 -> 9
A11: 10 | B11: Jyuratodus | C11: Jyuratodus | D11: Jyura | E11: =$A11 -> 10 | G11: 10 | H11: No Element | I11: =G11 -> 10
A12: 11 | B12: Anjanath | C12: Anjanath | D12: Anja | E12: =$A12 -> 11
A13: 12 | B13: Fulgur Anjanath | C13: Fulgur | D13: Fulgur | E13: =$A13 -> 12
A14: 13 | B14: Rathian | C14: Rathian | D14: Rathian | E14: =$A14 -> 13
A15: 14 | B15: Pink Rathian | C15: Pink Rathian | D15: Rath Heart | E15: =$A15 -> 14
A16: 15 | B16: Golden Rathian | C16: Golden Lune | D16: Golden Lune | E16: =$A16 -> 15
A17: 16 | B17: Legiana | C17: Legiana | D17: Legiana | E17: =$A17 -> 16
A18: 17 | B18: Diablos | C18: Diablos | D18: Diablos | E18: =$A18 -> 17
A19: 18 | B19: Black Diablos | C19: Black Diablos | D19: Diablos Nero | E19: =$A19 -> 18
A20: 19 | B20: Rathalos | C20: Rathalos | D20: Rathalos | E20: =$A20 -> 19
A21: 20 | B21: Azure Rathalos | C21: Azure Rathalos | D21: Rath Soul | E21: =$A21 -> 20
A22: 21 | B22: Silver Rathalos | C22: Silver Sol | D22: Silver Sol | E22: =$A22 -> 21
A23: 22 | B23: Radobaan | C23: Radobaan | D23: Baan | E23: =$A23 -> 22
... A59: 58 | B59: Malzeno | C59: Malzeno | D59: Malzeno | E59: =$A59 -> 58

Sheet Equipment
A1: id | B1: name | C1: set_name | D1: body_part | E1: body_part_name | F1: monster_name | G1: monster_id | H1: skill_slot | I1: weapon_low_level_alias | J1: weapon_attack | K1: weapon_affinity | L1: weapon_element_value | M1: weapon_element_type | N1: #dup_id
A2: 1 | B2: Leather Headgear | C2: Leather Set | D2: Helm | E2: Headgear | G2: =IF(ISNA(VLOOKUP(F2,Monster!B:E,4,FALSE)),0,VLOOKUP(F2,Monster!B:E,4,FALSE)) -> 0 | H2: 1 | N2: =$A2 -> 1
A3: 2 | B3: Leather Mail | C3: Leather Set | D3: Mail | E3: Mail | G3: =IF(ISNA(VLOOKUP(F3,Monster!B:E,4,FALSE)),0,VLOOKUP(F3,Monster!B:E,4,FALSE)) -> 0 | H3: 1 | N3: =$A3 -> 2
A4: 3 | B4: Leather Gloves | C4: Leather Set | D4: Vambraces | E4: Gloves | G4: =IF(ISNA(VLOOKUP(F4,Monster!B:E,4,FALSE)),0,VLOOKUP(F4,Monster!B:E,4,FALSE)) -> 0 | H4: 1 | N4: =$A4 -> 3
A5: 4 | B5: Leather Belt | C5: Leather Set | D5: Coil | E5: Belt | G5: =IF(ISNA(VLOOKUP(F5,Monster!B:E,4,FALSE)),0,VLOOKUP(F5,Monster!B:E,4,FALSE)) -> 0 | H5: 1 | N5: =$A5 -> 4
A6: 5 | B6: Leather Trousers | C6: Leather Set | D6: Greaves | E6: Trousers | G6: =IF(ISNA(VLOOKUP(F6,Monster!B:E,4,FALSE)),0,VLOOKUP(F6,Monster!B:E,4,FALSE)) -> 0 | H6: 1 | N6: =$A6 -> 5
A7: 6 | B7: Alloy Helm | C7: Alloy Set | D7: Helm | E7: Helm | G7: =IF(ISNA(VLOOKUP(F7,Monster!B:E,4,FALSE)),0,VLOOKUP(F7,Monster!B:E,4,FALSE)) -> 0 | H7: 1 | N7: =$A7 -> 6
A8: 7 | B8: Alloy Mail | C8: Alloy Set | D8: Mail | E8: Mail | G8: =IF(ISNA(VLOOKUP(F8,Monster!B:E,4,FALSE)),0,VLOOKUP(F8,Monster!B:E,4,FALSE)) -> 0 | H8: 1 | N8: =$A8 -> 7
A9: 8 | B9: Alloy Vambraces | C9: Alloy Set | D9: Vambraces | E9: Vambraces | G9: =IF(ISNA(VLOOKUP(F9,Monster!B:E,4,FALSE)),0,VLOOKUP(F9,Monster!B:E,4,FALSE)) -> 0 | H9: 1 | N9: =$A9 -> 8
A10: 9 | B10: Alloy Coil | C10: Alloy Set | D10: Coil | E10: Coil | G10: =IF(ISNA(VLOOKUP(F10,Monster!B:E,4,FALSE)),0,VLOOKUP(F10,Monster!B:E,4,FALSE)) -> 0 | H10: 1 | N10: =$A10 -> 9
A11: 10 | B11: Alloy Greaves | C11: Alloy Set | D11: Greaves | E11: Greaves | G11: =IF(ISNA(VLOOKUP(F11,Monster!B:E,4,FALSE)),0,VLOOKUP(F11,Monster!B:E,4,FALSE)) -> 0 | H11: 1 | N11: =$A11 -> 10
A12: 11 | B12: Jagras Helm | C12: Jagras Set | D12: Helm | E12: Helm | F12: Great Jagras | G12: =IF(ISNA(VLOOKUP(F12,Monster!B:E,4,FALSE)),0,VLOOKUP(F12,Monster!B:E,4,FALSE)) -> 1 | H12: 2 | N12: =$A12 -> 11
A13: 12 | B13: Jagras Mail | C13: Jagras Set | D13: Mail | E13: Mail | F13: Great Jagras | G13: =IF(ISNA(VLOOKUP(F13,Monster!B:E,4,FALSE)),0,VLOOKUP(F13,Monster!B:E,4,FALSE)) -> 1 | H13: 1 | N13: =$A13 -> 12
A14: 13 | B14: Jagras Vambraces | C14: Jagras Set | D14: Vambraces | E14: Vambraces | F14: Great Jagras | G14: =IF(ISNA(VLOOKUP(F14,Monster!B:E,4,FALSE)),0,VLOOKUP(F14,Monster!B:E,4,FALSE)) -> 1 | H14: 1 | N14: =$A14 -> 13
A15: 14 | B15: Jagras Coil | C15: Jagras Set | D15: Coil | E15: Coil | F15: Great Jagras | G15: =IF(ISNA(VLOOKUP(F15,Monster!B:E,4,FALSE)),0,VLOOKUP(F15,Monster!B:E,4,FALSE)) -> 1 | H15: 1 | N15: =$A15 -> 14
A16: 15 | B16: Jagras Greaves | C16: Jagras Set | D16: Greaves | E16: Greaves | F16: Great Jagras | G16: =IF(ISNA(VLOOKUP(F16,Monster!B:E,4,FALSE)),0,VLOOKUP(F16,Monster!B:E,4,FALSE)) -> 1 | H16: 1 | N16: =$A16 -> 15
A17: 16 | B17: Kulu Headpiece | C17: Kulu Set | D17: Helm | E17: Headpiece | F17: Kulu-Ya-Ku | G17: =IF(ISNA(VLOOKUP(F17,Monster!B:E,4,FALSE)),0,VLOOKUP(F17,Monster!B:E,4,FALSE)) -> 2 | H17: 1 | N17: =$A17 -> 16
A18: 17 | B18: Kulu Mail | C18: Kulu Set | D18: Mail | E18: Mail | F18: Kulu-Ya-Ku | G18: =IF(ISNA(VLOOKUP(F18,Monster!B:E,4,FALSE)),0,VLOOKUP(F18,Monster!B:E,4,FALSE)) -> 2 | H18: 2 | N18: =$A18 -> 17
A19: 18 | B19: Kulu Vambraces | C19: Kulu Set | D19: Vambraces | E19: Vambraces | F19: Kulu-Ya-Ku | G19: =IF(ISNA(VLOOKUP(F19,Monster!B:E,4,FALSE)),0,VLOOKUP(F19,Monster!B:E,4,FALSE)) -> 2 | H19: 1 | N19: =$A19 -> 18
A20: 19 | B20: Kulu Coil | C20: Kulu Set | D20: Coil | E20: Coil | F20: Kulu-Ya-Ku | G20: =IF(ISNA(VLOOKUP(F20,Monster!B:E,4,FALSE)),0,VLOOKUP(F20,Monster!B:E,4,FALSE)) -> 2 | H20: 2 | N20: =$A20 -> 19
A21: 20 | B21: Kulu Greaves | C21: Kulu Set | D21: Greaves | E21: Greaves | F21: Kulu-Ya-Ku | G21: =IF(ISNA(VLOOKUP(F21,Monster!B:E,4,FALSE)),0,VLOOKUP(F21,Monster!B:E,4,FALSE)) -> 2 | H21: 1 | N21: =$A21 -> 20
A22: 21 | B22: Pukei Hood | C22: Pukei Set | D22: Helm | E22: Helm | F22: Pukei-Pukei | G22: =IF(ISNA(VLOOKUP(F22,Monster!B:E,4,FALSE)),0,VLOOKUP(F22,Monster!B:E,4,FALSE)) -> 3 | H22: 1 | N22: =$A22 -> 21
A23: 22 | B23: Pukei Mail | C23: Pukei Set | D23: Mail | E23: Mail | F23: Pukei-Pukei | G23: =IF(ISNA(VLOOKUP(F23,Monster!B:E,4,FALSE)),0,VLOOKUP(F23,Monster!B:E,4,FALSE)) -> 3 | H23: 1 | N23: =$A23 -> 22
... A66: 65 | B66: Anja Greaves | C66: Anjanath Set | D66: Greaves | E66: Greaves | F66: Anjanath | G66: =IF(ISNA(VLOOKUP(F66,Monster!B:E,4,FALSE)),0,VLOOKUP(F66,Monster!B:E,4,FALSE)) -> 11 | H66: 1 | N66: =$A66 -> 65
A67: 61 | B67: Fulgur Helm | C67: Fulgur Set | D67: Helm | E67: Helm | F67: Fulgur Anjanath | G67: =IF(ISNA(VLOOKUP(F67,Monster!B:E,4,FALSE)),0,VLOOKUP(F67,Monster!B:E,4,FALSE)) -> 12 | H67: 1 | I67: =VLOOKUP(G67,Monster!A:E,4,FALSE) & " " & E67 -> Fulgur Helm | J67: =VLOOKUP(G67,Monster!A:E,3,FALSE) & " Set" -> Fulgur Set | N67: =$A67 -> 61
A68: 62 | B68: Fulgur Mail | C68: Fulgur Set | D68: Mail | E68: Mail | F68: Fulgur Anjanath | G68: =IF(ISNA(VLOOKUP(F68,Monster!B:E,4,FALSE)),0,VLOOKUP(F68,Monster!B:E,4,FALSE)) -> 12 | H68: 1 | I68: =VLOOKUP(G68,Monster!A:E,4,FALSE) & " " & E68 -> Fulgur Mail | J68: =VLOOKUP(G68,Monster!A:E,3,FALSE) & " Set" -> Fulgur Set | N68: =$A68 -> 62
A69: 63 | B69: Fulgur Vambraces | C69: Fulgur Set | D69: Vambraces | E69: Vambraces | F69: Fulgur Anjanath | G69: =IF(ISNA(VLOOKUP(F69,Monster!B:E,4,FALSE)),0,VLOOKUP(F69,Monster!B:E,4,FALSE)) -> 12 | H69: 1 | I69: =VLOOKUP(G69,Monster!A:E,4,FALSE) & " " & E69 -> Fulgur Vambraces | J69: =VLOOKUP(G69,Monster!A:E,3,FALSE) & " Set" -> Fulgur Set | N69: =$A69 -> 63
A70: 64 | B70: Fulgur Coil | C70: Fulgur Set | D70: Coil | E70: Coil | F70: Fulgur Anjanath | G70: =IF(ISNA(VLOOKUP(F70,Monster!B:E,4,FALSE)),0,VLOOKUP(F70,Monster!B:E,4,FALSE)) -> 12 | H70: 1 | I70: =VLOOKUP(G70,Monster!A:E,4,FALSE) & " " & E70 -> Fulgur Coil | J70: =VLOOKUP(G70,Monster!A:E,3,FALSE) & " Set" -> Fulgur Set | N70: =$A70 -> 64
A71: 65 | B71: Fulgur Greaves | C71: Fulgur Set | D71: Greaves | E71: Greaves | F71: Fulgur Anjanath | G71: =IF(ISNA(VLOOKUP(F71,Monster!B:E,4,FALSE)),0,VLOOKUP(F71,Monster!B:E,4,FALSE)) -> 12 | H71: 1 | I71: =VLOOKUP(G71,Monster!A:E,4,FALSE) & " " & E71 -> Fulgur Greaves | J71: =VLOOKUP(G71,Monster!A:E,3,FALSE) & " Set" -> Fulgur Set | N71: =$A71 -> 65
A72: 66 | B72: Rathian Helm | C72: Rathian Set | D72: Helm | E72: Helm | F72: Rathian | G72: =IF(ISNA(VLOOKUP(F72,Monster!B:E,4,FALSE)),0,VLOOKUP(F72,Monster!B:E,4,FALSE)) -> 13 | H72: 1 | N72: =$A72 -> 66
A73: 67 | B73: Rathian Mail | C73: Rathian Set | D73: Mail | E73: Mail | F73: Rathian | G73: =IF(ISNA(VLOOKUP(F73,Monster!B:E,4,FALSE)),0,VLOOKUP(F73,Monster!B:E,4,FALSE)) -> 13 | H73: 1 | N73: =$A73 -> 67
A74: 68 | B74: Rathian Vambraces | C74: Rathian Set | D74: Vambraces | E74: Vambraces | F74: Rathian | G74: =IF(ISNA(VLOOKUP(F74,Monster!B:E,4,FALSE)),0,VLOOKUP(F74,Monster!B:E,4,FALSE)) -> 13 | H74: 1 | N74: =$A74 -> 68
A75: 69 | B75: Rathian Coil | C75: Rathian Set | D75: Coil | E75: Coil | F75: Rathian | G75: =IF(ISNA(VLOOKUP(F75,Monster!B:E,4,FALSE)),0,VLOOKUP(F75,Monster!B:E,4,FALSE)) -> 13 | H75: 1 | N75: =$A75 -> 69
A76: 70 | B76: Rathian Greaves | C76: Rathian Set | D76: Greaves | E76: Greaves | F76: Rathian | G76: =IF(ISNA(VLOOKUP(F76,Monster!B:E,4,FALSE)),0,VLOOKUP(F76,Monster!B:E,4,FALSE)) -> 13 | H76: 2 | N76: =$A76 -> 70
A77: 71 | B77: Rath Heart Helm | C77: Pink Rathian Set | D77: Helm | E77: Helm | F77: Pink Rathian | G77: =IF(ISNA(VLOOKUP(F77,Monster!B:E,4,FALSE)),0,VLOOKUP(F77,Monster!B:E,4,FALSE)) -> 14 | H77: 1 | N77: =$A77 -> 71
A78: 72 | B78: Rath Heart Mail | C78: Pink Rathian Set | D78: Mail | E78: Mail | F78: Pink Rathian | G78: =IF(ISNA(VLOOKUP(F78,Monster!B:E,4,FALSE)),0,VLOOKUP(F78,Monster!B:E,4,FALSE)) -> 14 | H78: 1 | N78: =$A78 -> 72
A79: 73 | B79: Rath Heart Braces | C79: Pink Rathian Set | D79: Vambraces | E79: Braces | F79: Pink Rathian | G79: =IF(ISNA(VLOOKUP(F79,Monster!B:E,4,FALSE)),0,VLOOKUP(F79,Monster!B:E,4,FALSE)) -> 14 | H79: 1 | N79: =$A79 -> 73
A80: 74 | B80: Rath Heart Coil | C80: Pink Rathian Set | D80: Coil | E80: Coil | F80: Pink Rathian | G80: =IF(ISNA(VLOOKUP(F80,Monster!B:E,4,FALSE)),0,VLOOKUP(F80,Monster!B:E,4,FALSE)) -> 14 | H80: 1 | N80: =$A80 -> 74
A81: 75 | B81: Rath Heart Greaves | C81: Pink Rathian Set | D81: Greaves | E81: Greaves | F81: Pink Rathian | G81: =IF(ISNA(VLOOKUP(F81,Monster!B:E,4,FALSE)),0,VLOOKUP(F81,Monster!B:E,4,FALSE)) -> 14 | H81: 1 | N81: =$A81 -> 75
A82: 76 | B82: Golden Lunehelm | C82: Golden Lune Set | D82: Helm | E82: Helm | F82: Golden Rathian | G82: =IF(ISNA(VLOOKUP(F82,Monster!B:E,4,FALSE)),0,VLOOKUP(F82,Monster!B:E,4,FALSE)) -> 15 | H82: 1 | N82: =$A82 -> 76
...

Sheet Skill
A1: id | B1: name | C1: max_level | E1: Lv.1 | F1: Lv.2 | G1: Lv.3 | H1: Lv.4 | I1: Lv.5
B2: Advanced Attack Boost | C2: 2 | E2: Increases attack power by 150 when Attack Boost Lv5+ is active. | F2: Increases attack power by 350 when Attack Boost Lv5+ is active.
B3: Aggressive Dodger | C3: 5 | E3: Any attack performed following a perfect evade has its damage increased by 20%. | F3: Any attack performed following a perfect evade has its damage increased by 30%. | G3: Any attack performed following a perfect evade has its damage increased by 40%. | H3: Any attack performed following a perfect evade has its damage increased by 50%. | I3: Any attack performed following a perfect evade has its damage increased by 60%.
B4: Artful Dodger | C4: 5 | E4: Makes perfect evades ever so slightly easier to perform. | F4: Makes perfect evades slightly easier to perform. | G4: Makes perfect evades moderately easier to perform. | H4: Makes perfect evades much easier to perform. | I4: Makes perfect evades significantly easier to perform.
B5: Artillery | C5: 5 | E5: Increases damage of gunlance's Shelling/Wyvern's Fire, charge blades's phial attacks, sticky ammo, and wyvern ammo by 10%. | F5: Increases damage of gunlance's ammo/Wyvern's Fire attacks, charge blade's phial attacks, and sticky ammo by 15% | G5: Increases damage of gunlance's Shelling/Wyvern's Fire, charge blades's phial attacks, sticky ammo, and wyvern ammo by 20%. Increases gunlance's ammo and charge blade's phial amount by 1. | H5: Increases damage of gunlance's Shelling/Wyvern's Fire, charge blades's phial attacks, sticky ammo, and wyvern ammo by 30%. Increases gunlance's ammo and charge blade's phial amount by 1. | I5: Increases damage of gunlance's Shelling/Wyvern's Fire, charge blades's phial attacks, sticky ammo, and wyvern ammo by 40%. Increases gunlance's ammo and charge blade's phial amount by 1.
B6: Attack Boost | C6: 5 | E6: Increases attack power by 20. | F6: Increases attack power by 40. | G6: Increases attack power by 60. | H6: Increases attack power by 80. | I6: Increases attack power by 120.
B7: Ballistics | C7: 3 | E7: Slightly increases the Critical Range of your ammo/arrows. | F7: Moderately increases the Critical Range of your ammo/arrows. | G7: Significantly increases the Critical Range of your ammo/arrows.
B8: Balloon Charge | C8: 1 | E8: Whenever you charge up an attack/Special Skill to the max, your weapon will expand, increasing damage.
B9: Blast Attack | C9: 5 | E9: Increase weapon's blast buildup value by 50. | F9: Increase weapon's blast buildup value by 75. | G9: Increase weapon's blast buildup value by 100. | H9: Increase weapon's blast buildup value by 125. | I9: Increase weapon's blast buildup value by 150.
B10: Blast Resistance | C10: 3 | E10: 30% chance of preventing blastblight status when damaged by a blast element attack | F10: 60% chance of preventing blastblight status when damaged by a blast element attack | G10: Prevents blastblight
B11: Bleeding Edge | C11: 3 | E11: Reduces damage received from bleeding. | F11: In addition to the effects of Lv1, increases affinity by 50% when bleeding. | G11: In addition to the effects of Lv2, grants bleeding status both at the start of a hunt and after performing multiple actions.
B12: Bleeding Resistance | C12: 3 | E12: 30% chance of preventing bleeding status when damaged by a bleeding-inducing attack. | F12: 60% chance of preventing bleeding status when damaged by a bleeding-inducing attack. | G12: Prevents bleeding.
B13: Blunt Force | C13: 5 | E13: Increases the damage of the hammer's Charged Attack and the hunting horn's Echo Attack by 15%. | F13: Increases the damage of the hammer's Charged Attack and the hunting horn's Echo Attack by 25%. | G13: Increases the damage of the hammer's Charged Attack and the hunting horn's Echo Attack by 40%. | H13: Increases the damage of the hammer's Charged Attack and the hunting horn's Echo Attack by 55%. | I13: Increases the damage of the hammer's Charged Attack and the hunting horn's Echo Attack by 70%.
B14: Bubbly Dance | C14: 3 | E14: Reduces the effects of bubbleblight. | F14: Reduces the effects of bubbleblight and makes it easier to perform well-times evades. | G14: In addition to the effects of Lv2, grants bubbleblight status after performing an evasive action multiple times.
B15: Buildup Boost | C15: 5 | E15: Increases damage by 10% if poison/paralysis/sleep/blast buildup occurs when hitting a monster. | F15: Increases damage by 20% if poison/paralysis/sleep/blast buildup occurs when hitting a monster. | G15: Increases damage by 30% if poison/paralysis/sleep/blast buildup occurs when hitting a monster. | H15: Increases damage by 40% if poison/paralysis/sleep/blast buildup occurs when hitting a monster. | I15: Increases damage by 50% if poison/paralysis/sleep/blast buildup occurs when hitting a monster.
B16: Burst | C16: 5 | E16: Landing consecutive hits in a short span of time increases attack power by 5% for 4 seconds. | F16: Landing consecutive hits in a short span of time increases attack power by 10% for 4 seconds. | G16: Landing consecutive hits in a short span of time increases attack power by 15% for 4 seconds. | H16: Landing consecutive hits in a short span of time increases attack power by 20% for 4 seconds. | I16: Landing consecutive hits in a short span of time increases attack power by 30% for 4 seconds.
B17: Chameleos Venomist | C17: 3 | E17: Halves poison/venom status duration, and makes it slightly easier to build up poison status on a monster. | F17: Halves poison/venom status duration, and makes it moderately easier to build up poison status on a monster. | G17: Halves poison/venom status duration, and makes it significantly easier to build up poison status on a monster.
B18: Concentration | C18: 5 | E18: Increases Special Gauge fill rate by 5%. | F18: Increases Special Gauge fill rate by 10%. | G18: Increases Special Gauge fill rate by 15%. | H18: Increases Special Gauge fill rate by 20%. | I18: Increases Special Gauge fill rate by 30%.
B19: Critical Boost | C19: 5 | E19: Increases the damage multiplier of critical hits to 130%. | F19: Increases the damage multiplier of critical hits to 135%. | G19: Increases the damage multiplier of critical hits to 140%. | H19: Increases the damage multiplier of critical hits to 145%. | I19: Increases the damage multiplier of critical hits to 150%.
B20: Critical Element | C20: 5 | E20: Weapon's elemental attack power increases by 30% when landing a critical hit. | F20: Weapon's elemental attack power increases by 40% when landing a critical hit. | G20: Weapon's elemental attack power increases by 50% when landing a critical hit. | H20: Weapon's elemental attack power increases by 60% when landing a critical hit. | I20: Weapon's elemental attack power increases by 80% when landing a critical hit.
B21: Critical Eye | C21: 5 | E21: Increases affinity by 10%. | F21: Increases affinity by 15%. | G21: Increases affinity by 20%. | H21: Increases affinity by 30%. | I21: Increases affinity by 40%.
B22: Critical Ferocity | C22: 5 | E22: Reduces weapon's affinity by 10%, but grants a small chance of increasing negative affinity damage to 150%. | F22: Reduces weapon's affinity by 15%, but grants a small chance of increasing negative affinity damage to 175%. | G22: Reduces weapon's affinity by 20%, but grants a small chance of increasing negative affinity damage to 200%. | H22: Reduces weapon's affinity by 25%, but grants a small chance of increasing negative affinity damage to 225%. | I22: Reduces weapon's affinity by 30%, but grants a small chance of increasing negative affinity damage to 250%.
B23: Dauntless | C23: 5 | E23: Damage Increases by 5% for 6 seconds after performing a forward evasion. | F23: Damage Increases by 10% for 6 seconds after performing a forward evasion. | G23: Damage Increases by 15% for 6 seconds after performing a forward evasion. | H23: Damage Increases by 20% for 8 seconds after performing a forward evasion. | I23: Damage Increases by 25% for 10 seconds after performing a forward evasion.
B24: Defense Boost | C24: 5 | E24: Increases defense by 20. | F24: Increases defense by 40. | G24: Increases defense by 60. | H24: Increases defense by 80. | I24: Increases defense by 100.
B25: Defensive Loading | C25: 3 | E25: Reloads phial/ammo of charge blade/gunlance/heavy bowgun by 1 after guarding against a monster's attack. | F25: Reloads phial/ammo of charge blade/gunlance/heavy bowgun by 2 after guarding against a monster's attack. | G25: Reloads phial/ammo of charge blade/gunlance/heavy bowgun by 3 after guarding against a monster's attack.
B26: Divine Blessing | C26: 5 | E26: 30% chance of reducing damage from a monster's attack by 50%. | F26: 40% chance of reducing damage from a monster's attack by 50%. | G26: 50% chance of reducing damage from a monster's attack by 50%. | H26: 50% chance of reducing damage from a monster's attack by 60%. | I26: 50% chance of reducing damage from a monster's attack by 80%.
B27: Dragon Attack | C27: 5 | E27: Increases weapon's dragon-element value by 50. | F27: Increases weapon's dragon-element value by 100. | G27: Increases weapon's dragon-element value by 200. | H27: Increases weapon's dragon-element value by 350. | I27: Increases weapon's dragon-element value by 500.
B28: Earplugs | C28: 5 | E28: Slightly reduces the effects of weak monster roars. | F28: Moderately reduces the effects of weak monster roars. | G28: Nullifies the effects of weak monster roars, and slightly reduces the effects of strong monster roars. | H28: Nullifies the effects of weak monster roars, and moderately reduces the effects of strong monster roars. | I28: Nullifies the effects of both weak and strong monster roars.
B29: Evade Extender | C29: 5 | E29: Very slightly extends evasion distance. | F29: Slightly extends evasion distance. | G29: Moderately extends evasion distance. | H29: Greatly extends evasion distance. | I29: Massively extends evasion distance.
B30: Evading Reload | C30: 3 | E30: Grants a 30% chance of phials/ammo being refilled by 1 when evading while equipped with a gunlance, charge blade, light bowgun or heavy bowgun. | F30: Grants a 50% chance of phials/ammo being refilled by 1 when evading while equipped with a gunlance, charge blade, light bowgun or heavy bowgun. | G30: Grants a 50% chance of phials/ammo being refilled by 2 when evading while equipped with a gunlance, charge blade, light bowgun or heavy bowgun.
B31: Evasive Concentration | C31: 5 | E31: Fills Special Gauge by 7% after performing a perfect evade. | F31: Fills Special Gauge by 10% after performing a perfect evade. | G31: Fills Special Gauge by 12% after performing a perfect evade. | H31: Fills Special Gauge by 15% after performing a perfect evade. | I31: Fills Special Gauge by 20% after performing a perfect evade.
B32: Fighting Spirit | C32: 5 | E32: When the Special Gauge becomes full, damage dealt increases by 10% for 20 seconds. | F32: When the Special Gauge becomes full, damage dealt increases by 15% for 20 seconds. | G32: When the Special Gauge becomes full, damage dealt increases by 20% for 20 seconds. | H32: When the Special Gauge becomes full, damage dealt increases by 25% for 20 seconds. | I32: When the Special Gauge becomes full, damage dealt increases by 30% for 20 seconds.
B33: Final Shot | C33: 5 | E33: Increases the damage of the last remaining ammo/phial by 10% when using a gunlance, charge blade, light bowgun or heavy bowgun. | F33: Increases the damage of the last remaining ammo/phial by 20% when using a gunlance, charge blade, light bowgun or heavy bowgun. | G33: Increases the damage of the last remaining ammo/phial by 35% when using a gunlance, charge blade, light bowgun or heavy bowgun. | H33: Increases the damage of the last remaining ammo/phial by 45% when using a gunlance, charge blade, light bowgun or heavy bowgun. | I33: Increases the damage of the last remaining ammo/phial by 60% when using a gunlance, charge blade, light bowgun or heavy bowgun.
B34: Fire Attack | C34: 5 | E34: Increases weapon's fire-element value by 50. | F34: Increases weapon's fire-element value by 100. | G34: Increases weapon's fire-element value by 200. | H34: Increases weapon's fire-element value by 350. | I34: Increases weapon's fire-element value by 500.
B35: Fire Resistance | C35: 3 | E35: Decreases damage from fire-element monsters by 15%. | F35: Decreases damage from fire-element monsters by 30%. | G35: Decreases damage from fire-element monsters by 50%.
B36: Firm Foothold | C36: 3 | E36: Very slightly reduces knockback when taking damage. | F36: Slightly reduces knockback when taking damage. | G36: Moderately reduces knockback when taking damage.
B37: Focus | C37: 5 | E37: Shortens charging time for weapons with charge attacks by 5%, and increases the fill rate of the Spirit Gauge by 5%. | F37: Shortens charging time for weapons with charge attacks by 10%, and increases the fill rate of the Spirit Gauge by 10%. | G37: Shortens charging time for weapons with charge attacks by 15%, and increases the fill rate of the Spirit Gauge by 15%. | H37: Shortens charging time for weapons with charge attacks by 20%, and increases the fill rate of the Spirit Gauge by 20%. | I37: Shortens charging time for weapons with charge attacks by 30%, and increases the fill rate of the Spirit Gauge by 30%.
B38: Fortify | C38: 5 | E38: Increases attack power by 10% for 10 seconds each time you revive after fainting during a hunt. | F38: Increases attack power by 15% for 10 seconds each time you revive after fainting during a hunt. | G38: Increases attack power by 20% for 10 seconds each time you revive after fainting during a hunt. | H38: Increases attack power by 30% for 10 seconds each time you revive after fainting during a hunt. | I38: Increases attack power by 40% for 10 seconds each time you revive after fainting during a hunt.
B39: Guard | C39: 5 | E39: Very slightly reduces damage and knockback when guarding against monster attacks. | F39: Slightly reduces damage and knockback when guarding against monster attacks. | G39: Moderately reduces damage and knockback when guarding against monster attacks. | H39: Greatly reduces damage and knockback when guarding against monster attacks. | I39: Massively reduces damage and knockback when guarding against monster attacks.
B40: Guard Up | C40: 1 | E40: Allows you to guard against attacks that usually cannot be blocked.
...

Sheet Equipment_Skill
A1: id | B1: equipment_name | C1: skill_name | D1: max_level
A2: 1 | B2: Leather Headgear | C2: Critical Eye | D2: 1 | E2: =VLOOKUP(C2,Skill!B:C,2,FALSE) -> 5 | F2: =VLOOKUP(B2,Equipment!B:N,3,FALSE) -> Helm
A3: 2 | B3: Leather Headgear | C3: Ice Resistance | D3: 1 | E3: =VLOOKUP(C3,Skill!B:C,2,FALSE) -> 3 | F3: =VLOOKUP(B3,Equipment!B:N,3,FALSE) -> Helm
A4: 3 | B4: Leather Mail | C4: Attack Boost | D4: 1 | E4: =VLOOKUP(C4,Skill!B:C,2,FALSE) -> 5 | F4: =VLOOKUP(B4,Equipment!B:N,3,FALSE) -> Mail
A5: 4 | B5: Leather Mail | C5: Fire Resistance | D5: 1 | E5: =VLOOKUP(C5,Skill!B:C,2,FALSE) -> 3 | F5: =VLOOKUP(B5,Equipment!B:N,3,FALSE) -> Mail
A6: 5 | B6: Leather Gloves | C6: Defense Boost | D6: 1 | E6: =VLOOKUP(C6,Skill!B:C,2,FALSE) -> 5 | F6: =VLOOKUP(B6,Equipment!B:N,3,FALSE) -> Vambraces
A7: 6 | B7: Leather Gloves | C7: Thunder Resistance | D7: 1 | E7: =VLOOKUP(C7,Skill!B:C,2,FALSE) -> 3 | F7: =VLOOKUP(B7,Equipment!B:N,3,FALSE) -> Vambraces
A8: 7 | B8: Leather Belt | C8: Health Boost | D8: 1 | E8: =VLOOKUP(C8,Skill!B:C,2,FALSE) -> 5 | F8: =VLOOKUP(B8,Equipment!B:N,3,FALSE) -> Coil
A9: 8 | B9: Leather Belt | C9: Water Resistance | D9: 1 | E9: =VLOOKUP(C9,Skill!B:C,2,FALSE) -> 3 | F9: =VLOOKUP(B9,Equipment!B:N,3,FALSE) -> Coil
A10: 9 | B10: Leather Trousers | C10: Poison Resistance | D10: 1 | E10: =VLOOKUP(C10,Skill!B:C,2,FALSE) -> 3 | F10: =VLOOKUP(B10,Equipment!B:N,3,FALSE) -> Greaves
A11: 10 | B11: Leather Trousers | C11: Paralysis Resistance | D11: 1 | E11: =VLOOKUP(C11,Skill!B:C,2,FALSE) -> 3 | F11: =VLOOKUP(B11,Equipment!B:N,3,FALSE) -> Greaves
A12: 11 | B12: Alloy Helm | C12: Earplugs | D12: 3 | E12: =VLOOKUP(C12,Skill!B:C,2,FALSE) -> 5 | F12: =VLOOKUP(B12,Equipment!B:N,3,FALSE) -> Helm
A13: 12 | B13: Alloy Mail | C13: Tremor Resistance | D13: 2 | E13: =VLOOKUP(C13,Skill!B:C,2,FALSE) -> 3 | F13: =VLOOKUP(B13,Equipment!B:N,3,FALSE) -> Mail
... A538: 417 | B538: Swimmer Flippers | C538: Shared Shield | D538: 2 | E538: =VLOOKUP(C538,Skill!B:C,2,FALSE) -> 5 | F538: =VLOOKUP(B538,Equipment!B:N,3,FALSE) -> Greaves

Sheet Weapon
A1: id | B1: name | C1: set_name | D1: body_part | E1: body_part_name | F1: monster_name | G1: monster_id | H1: skill_slot | I1: weapon_low_level_alias | J1: weapon_attack | K1: weapon_affinity | L1: weapon_element_value | M1: weapon_element_type | N1: #dup_id
B2: Steel Knife | C2: Leather Set | D2: Weapon | E2: Sword & Shield | G2: =IF(ISNA(VLOOKUP(F2,Monster!B:E,4,FALSE)),0,VLOOKUP(F2,Monster!B:E,4,FALSE)) -> 0 | I2: Hunter's Knife | J2: 1596 | K2: 0 | L2: 0 | M2: No Element | O2: =((NOT(ISNA(VLOOKUP(M2,Monster!$H$2:$I$6,2,FALSE)))*L2)+J2)*(1+K2/100*0.25) -> 1596 | P2: Poison Resistance | Q2: 2
B3: Jagras Garotte | C3: Jagras Set | D3: Weapon | E3: Sword & Shield | F3: Great Jagras | G3: =IF(ISNA(VLOOKUP(F3,Monster!B:E,4,FALSE)),0,VLOOKUP(F3,Monster!B:E,4,FALSE)) -> 1 | I3: Jagras Edge | J3: 1373 | K3: 0 | L3: 607 | M3: Water | O3: =((NOT(ISNA(VLOOKUP(M3,Monster!$H$2:$I$6,2,FALSE)))*L3)+J3)*(1+K3/100*0.25) -> 1980 | P3: Health Boost | Q3: 2
C4: Kulu Set | D4: Weapon | E4: Sword & Shield | F4: Kulu-Ya-Ku | G4: =IF(ISNA(VLOOKUP(F4,Monster!B:E,4,FALSE)),0,VLOOKUP(F4,Monster!B:E,4,FALSE)) -> 2 | L4: 0 | M4: No Element | O4: =((NOT(ISNA(VLOOKUP(M4,Monster!$H$2:$I$6,2,FALSE)))*L4)+J4)*(1+K4/100*0.25) -> 0 | P4: Fortify | Q4: 2
B5: Datura Blossom | C5: Pukei Set | D5: Weapon | E5: Sword & Shield | F5: Pukei-Pukei | G5: =IF(ISNA(VLOOKUP(F5,Monster!B:E,4,FALSE)),0,VLOOKUP(F5,Monster!B:E,4,FALSE)) -> 3 | I5: Blooming Knife | J5: 1596 | K5: 0 | L5: 400 | M5: Poison | O5: =((NOT(ISNA(VLOOKUP(M5,Monster!$H$2:$I$6,2,FALSE)))*L5)+J5)*(1+K5/100*0.25) -> 1596 | P5: Sneak Attack | Q5: 1
B6: Laguna Blossom | C6: Coral Pukei Set | D6: Weapon | E6: Sword & Shield | F6: Coral Pukei-Pukei | G6: =IF(ISNA(VLOOKUP(F6,Monster!B:E,4,FALSE)),0,VLOOKUP(F6,Monster!B:E,4,FALSE)) -> 4 | I6: Laguna Blossom | J6: 1221 | K6: 0 | L6: 1142 | M6: Water | O6: =((NOT(ISNA(VLOOKUP(M6,Monster!$H$2:$I$6,2,FALSE)))*L6)+J6)*(1+K6/100*0.25) -> 2363 | P6: Earplugs | Q6: 1
B7: Barroth Club | C7: Barroth Set | D7: Weapon | E7: Sword & Shield | F7: Barroth | G7: =IF(ISNA(VLOOKUP(F7,Monster!B:E,4,FALSE)),0,VLOOKUP(F7,Monster!B:E,4,FALSE)) -> 5 | I7: Carapace Edge | J7: 1756 | K7: 0 | L7: 0 | M7: No Element | O7: =((NOT(ISNA(VLOOKUP(M7,Monster!$H$2:$I$6,2,FALSE)))*L7)+J7)*(1+K7/100*0.25) -> 1756 | P7: Defense Boost | Q7: 2
B8: Malady's Tabar | C8: Girros Set | D8: Weapon | E8: Sword & Shield | F8: Great Girros | G8: =IF(ISNA(VLOOKUP(F8,Monster!B:E,4,FALSE)),0,VLOOKUP(F8,Monster!B:E,4,FALSE)) -> 6 | I8: Girros Knife | J8: 1596 | K8: 0 | L8: 400 | M8: Paralysis | O8: =((NOT(ISNA(VLOOKUP(M8,Monster!$H$2:$I$6,2,FALSE)))*L8)+J8)*(1+K8/100*0.25) -> 1596 | P8: Sneak Attack | Q8: 1
B9: Lightning Nemesis | C9: Kadachi Set | D9: Weapon | E9: Sword & Shield | F9: Tobi-Kadachi | G9: =IF(ISNA(VLOOKUP(F9,Monster!B:E,4,FALSE)),0,VLOOKUP(F9,Monster!B:E,4,FALSE)) -> 7 | I9: Thunder Edge | J9: 1293 | K9: 0 | L9: 910 | M9: Thunder | O9: =((NOT(ISNA(VLOOKUP(M9,Monster!$H$2:$I$6,2,FALSE)))*L9)+J9)*(1+K9/100*0.25) -> 2203 | P9: Evade Extender | Q9: 1
B10: Lumu Tabar | C10: Paolumu Set | D10: Weapon | E10: Sword & Shield | F10: Paolumu | G10: =IF(ISNA(VLOOKUP(F10,Monster!B:E,4,FALSE)),0,VLOOKUP(F10,Monster!B:E,4,FALSE)) -> 8 | I10: Lumu Knife | J10: 1764 | K10: 0 | L10: 0 | M10: No Element | O10: =((NOT(ISNA(VLOOKUP(M10,Monster!$H$2:$I$6,2,FALSE)))*L10)+J10)*(1+K10/100*0.25) -> 1764 | P10: Divine Blessing | Q10: 2
B11: Nyx Tabar | C11: Nightshade Paolumu Set | D11: Weapon | E11: Sword & Shield | F11: Nightshade Paolumu | G11: =IF(ISNA(VLOOKUP(F11,Monster!B:E,4,FALSE)),0,VLOOKUP(F11,Monster!B:E,4,FALSE)) -> 9 | I11: Nyx Tabar | J11: 1756 | K11: 0 | L11: 300 | M11: Sleep | O11: =((NOT(ISNA(VLOOKUP(M11,Monster!$H$2:$I$6,2,FALSE)))*L11)+J11)*(1+K11/100*0.25) -> 1756 | P11: Sneak Attack | Q11: 1
B12: Rogue Wave | C12: Jyuratodus Set | D12: Weapon | E12: Sword & Shield | F12: Jyuratodus | G12: =IF(ISNA(VLOOKUP(F12,Monster!B:E,4,FALSE)),0,VLOOKUP(F12,Monster!B:E,4,FALSE)) -> 10 | I12: Aqua Messer | J12: 1293 | K12: 0 | L12: 910 | M12: Water | O12: =((NOT(ISNA(VLOOKUP(M12,Monster!$H$2:$I$6,2,FALSE)))*L12)+J12)*(1+K12/100*0.25) -> 2203 | P12: Last Stand | Q12: 1
B13: Flammensucher | C13: Anjanath Set | D13: Weapon | E13: Sword & Shield | F13: Anjanath | G13: =IF(ISNA(VLOOKUP(F13,Monster!B:E,4,FALSE)),0,VLOOKUP(F13,Monster!B:E,4,FALSE)) -> 11 | I13: Blazing Edge | J13: 1293 | K13: 0 | L13: 910 | M13: Fire | O13: =((NOT(ISNA(VLOOKUP(M13,Monster!$H$2:$I$6,2,FALSE)))*L13)+J13)*(1+K13/100*0.25) -> 2203 | P13: Rising Tide | Q13: 1
B14: Donnersieger | C14: Fulgur Set | D14: Weapon | E14: Sword & Shield | F14: Fulgur Anjanath | G14: =IF(ISNA(VLOOKUP(F14,Monster!B:E,4,FALSE)),0,VLOOKUP(F14,Monster!B:E,4,FALSE)) -> 12 | I14: Donnersieger | J14: 1197 | K14: 20 | L14: 1154 | M14: Thunder | O14: =((NOT(ISNA(VLOOKUP(M14,Monster!$H$2:$I$6,2,FALSE)))*L14)+J14)*(1+K14/100*0.25) -> 2468.55 | P14: Critical Element | Q14: 1
B15: Queen Rapier | C15: Rathian Set | D15: Weapon | E15: Sword & Shield | F15: Rathian | G15: =IF(ISNA(VLOOKUP(F15,Monster!B:E,4,FALSE)),0,VLOOKUP(F15,Monster!B:E,4,FALSE)) -> 13 | I15: Princess Rapier | J15: 1516 | K15: 0 | L15: 496 | M15: Poison | O15: =((NOT(ISNA(VLOOKUP(M15,Monster!$H$2:$I$6,2,FALSE)))*L15)+J15)*(1+K15/100*0.25) -> 1516 | P15: Health Boost | Q15: 2
B16: Royal Rose | C16: Pink Rathian Set | D16: Weapon | E16: Sword & Shield | F16: Pink Rathian | G16: =IF(ISNA(VLOOKUP(F16,Monster!B:E,4,FALSE)),0,VLOOKUP(F16,Monster!B:E,4,FALSE)) -> 14 | I16: Queen Rose | J16: 1756 | K16: 0 | L16: 300 | M16: Poison | O16: =((NOT(ISNA(VLOOKUP(M16,Monster!$H$2:$I$6,2,FALSE)))*L16)+J16)*(1+K16/100*0.25) -> 1756 | P16: Evade Extender | Q16: 1
... B18: Rimespire | C18: Legiana Set | D18: Weapon | E18: Sword & Shield | F18: Legiana | G18: =IF(ISNA(VLOOKUP(F18,Monster!B:E,4,FALSE)),0,VLOOKUP(F18,Monster!B:E,4,FALSE)) -> 16 | I18: Glacial Grace | J18: 1221 | K18: 0 | L18: 1142 | M18: Ice | O18: =((NOT(ISNA(VLOOKUP(M18,Monster!$H$2:$I$6,2,FALSE)))*L18)+J18)*(1+K18/100*0.25) -> 2363 | P18: Divine Blessing | Q18: 2
C19: Diablos Set | D19: Weapon | E19: Sword & Shield | F19: Diablos | G19: =IF(ISNA(VLOOKUP(F19,Monster!B:E,4,FALSE)),0,VLOOKUP(F19,Monster!B:E,4,FALSE)) -> 17 | L19: 0 | M19: No Element | O19: =((NOT(ISNA(VLOOKUP(M19,Monster!$H$2:$I$6,2,FALSE)))*L19)+J19)*(1+K19/100*0.25) -> 0 | P19: Heroics | Q19: 1
C20: Black Diablos Set | D20: Weapon | E20: Sword & Shield | F20: Black Diablos | G20: =IF(ISNA(VLOOKUP(F20,Monster!B:E,4,FALSE)),0,VLOOKUP(F20,Monster!B:E,4,FALSE)) -> 18 | L20: 0 | M20: No Element | O20: =((NOT(ISNA(VLOOKUP(M20,Monster!$H$2:$I$6,2,FALSE)))*L20)+J20)*(1+K20/100*0.25) -> 0 | P20: Partbreaker | Q20: 1
B21: Heat Edge | C21: Rathalos Set | D21: Weapon | E21: Sword & Shield | F21: Rathalos | G21: =IF(ISNA(VLOOKUP(F21,Monster!B:E,4,FALSE)),0,VLOOKUP(F21,Monster!B:E,4,FALSE)) -> 19 | I21: Flame Knife | J21: 1221 | K21: 0 | L21: 1142 | M21: Fire | O21: =((NOT(ISNA(VLOOKUP(M21,Monster!$H$2:$I$6,2,FALSE)))*L21)+J21)*(1+K21/100*0.25) -> 2363 | P21: Earplugs | Q21: 1
B22: Blue Corona | C22: Azure Rathalos Set | D22: Weapon | E22: Sword & Shield | F22: Azure Rathalos | G22: =IF(ISNA(VLOOKUP(F22,Monster!B:E,4,FALSE)),0,VLOOKUP(F22,Monster!B:E,4,FALSE)) -> 20 | I22: Blue Corona | J22: 1682 | K22: 0 | L22: 605 | M22: Fire | O22: =((NOT(ISNA(VLOOKUP(M22,Monster!$H$2:$I$6,2,FALSE)))*L22)+J22)*(1+K22/100*0.25) -> 2287 | P22: Special Boost | Q22: 1
B23: Platinum Dawn | C23: Silver Sol Set | D23: Weapon | E23: Sword & Shield | F23: Silver Rathalos | G23: =IF(ISNA(VLOOKUP(F23,Monster!B:E,4,FALSE)),0,VLOOKUP(F23,Monster!B:E,4,FALSE)) -> 21 | I23: Platinum Dawn | J23: 1258 | K23: 30 | L23: 1082 | M23: Fire | O23: =((NOT(ISNA(VLOOKUP(M23,Monster!$H$2:$I$6,2,FALSE)))*L23)+J23)*(1+K23/100*0.25) -> 2515.5 | P23: Critical Element | Q23: 2
B24: Baan Claw | C24: Radobaan Set | D24: Weapon | E24: Sword & Shield | F24: Radobaan | G24: =IF(ISNA(VLOOKUP(F24,Monster!B:E,4,FALSE)),0,VLOOKUP(F24,Monster!B:E,4,FALSE)) -> 22 | I24: Spiked Edge | J24: 1596 | K24: 0 | L24: 400 | M24: Sleep | O24: =((NOT(ISNA(VLOOKUP(M24,Monster!$H$2:$I$6,2,FALSE)))*L24)+J24)*(1+K24/100*0.25) -> 1596 | P24: Defense Boost | Q24: 2
C25: Banbaro Set | D25: Weapon | E25: Sword & Shield | F25: Banbaro | G25: =IF(ISNA(VLOOKUP(F25,Monster!B:E,4,FALSE)),0,VLOOKUP(F25,Monster!B:E,4,FALSE)) -> 23 | L25: 0 | M25: No Element | O25: =((NOT(ISNA(VLOOKUP(M25,Monster!$H$2:$I$6,2,FALSE)))*L25)+J25)*(1+K25/100*0.25) -> 0 | P25: Firm Foothold | Q25: 2
B26: Icicle Spike+ | C26: Barioth Set | D26: Weapon | E26: Sword & Shield | F26: Barioth | G26: =IF(ISNA(VLOOKUP(F26,Monster!B:E,4,FALSE)),0,VLOOKUP(F26,Monster!B:E,4,FALSE)) -> 24 | I26: Icicle Spike | J26: 1191 | K26: 20 | L26: 910 | M26: Ice | O26: =((NOT(ISNA(VLOOKUP(M26,Monster!$H$2:$I$6,2,FALSE)))*L26)+J26)*(1+K26/100*0.25) -> 2206.05 | P26: Evade Extender | Q26: 1
B27: Despot's Crookbolt | C27: Zinogre Set | D27: Weapon | E27: Sword & Shield | F27: Zinogre | G27: =IF(ISNA(VLOOKUP(F27,Monster!B:E,4,FALSE)),0,VLOOKUP(F27,Monster!B:E,4,FALSE)) -> 25 | I27: Usurper's Firebolt | J27: 1221 | K27: 0 | L27: 1142 | M27: Thunder | O27: =((NOT(ISNA(VLOOKUP(M27,Monster!$H$2:$I$6,2,FALSE)))*L27)+J27)*(1+K27/100*0.25) -> 2363 | P27: Artful Dodger | Q27: 1
C28: Tzitzi Set | D28: Weapon | E28: Sword & Shield | F28: Tzitzi-Ya-Ku | G28: =IF(ISNA(VLOOKUP(F28,Monster!B:E,4,FALSE)),0,VLOOKUP(F28,Monster!B:E,4,FALSE)) -> 26 | L28: 0 | M28: No Element | O28: =((NOT(ISNA(VLOOKUP(M28,Monster!$H$2:$I$6,2,FALSE)))*L28)+J28)*(1+K28/100*0.25) -> 0 | P28: Lock On | Q28: 1
C29: Odogaron Set | D29: Weapon | E29: Sword & Shield | F29: Odogaron | G29: =IF(ISNA(VLOOKUP(F29,Monster!B:E,4,FALSE)),0,VLOOKUP(F29,Monster!B:E,4,FALSE)) -> 27 | L29: 0 | M29: No Element | O29: =((NOT(ISNA(VLOOKUP(M29,Monster!$H$2:$I$6,2,FALSE)))*L29)+J29)*(1+K29/100*0.25) -> 0 | P29: Evasive Concentration | Q29: 1
C30: Death Garon Set | D30: Weapon | E30: Sword & Shield | F30: Ebony Odogaron | G30: =IF(ISNA(VLOOKUP(F30,Monster!B:E,4,FALSE)),0,VLOOKUP(F30,Monster!B:E,4,FALSE)) -> 28 | L30: 0 | M30: No Element | O30: =((NOT(ISNA(VLOOKUP(M30,Monster!$H$2:$I$6,2,FALSE)))*L30)+J30)*(1+K30/100*0.25) -> 0 | P30: Critical Boost | Q30: 1
B31: Fatal Bite | C31: Deviljho Set | D31: Weapon | E31: Sword & Shield | F31: Deviljho | G31: =IF(ISNA(VLOOKUP(F31,Monster!B:E,4,FALSE)),0,VLOOKUP(F31,Monster!B:E,4,FALSE)) -> 29 | I31: Fatal jho | J31: 1318 | K31: -30 | L31: 1261 | M31: Dragon | O31: =((NOT(ISNA(VLOOKUP(M31,Monster!$H$2:$I$6,2,FALSE)))*L31)+J31)*(1+K31/100*0.25) -> 2385.575 | P31: Slugger | Q31: 1
C32: Basarios Set | D32: Weapon | E32: Sword & Shield | F32: Basarios | G32: =IF(ISNA(VLOOKUP(F32,Monster!B:E,4,FALSE)),0,VLOOKUP(F32,Monster!B:E,4,FALSE)) -> 30 | L32: 0 | M32: No Element | O32: =((NOT(ISNA(VLOOKUP(M32,Monster!$H$2:$I$6,2,FALSE)))*L32)+J32)*(1+K32/100*0.25) -> 0 | P32: Heroics | Q32: 1
B33: Painful Razor | C33: Khezu Set | D33: Weapon | E33: Sword & Shield | F33: Khezu | G33: =IF(ISNA(VLOOKUP(F33,Monster!B:E,4,FALSE)),0,VLOOKUP(F33,Monster!B:E,4,FALSE)) -> 31 | I33: Khezu Razor | J33: 1194 | K33: 20 | L33: 913 | M33: Thunder | O33: =((NOT(ISNA(VLOOKUP(M33,Monster!$H$2:$I$6,2,FALSE)))*L33)+J33)*(1+K33/100*0.25) -> 2212.35 | P33: Peak Performance | Q33: 1
B34: Daora's Razor | C34: Kushala Set | D34: Weapon | E34: Sword & Shield | F34: Kushala Daora | G34: =IF(ISNA(VLOOKUP(F34,Monster!B:E,4,FALSE)),0,VLOOKUP(F34,Monster!B:E,4,FALSE)) -> 32 | I34: Daora's Razor | J34: 1553 | K34: 0 | L34: 974 | M34: Ice | O34: =((NOT(ISNA(VLOOKUP(M34,Monster!$H$2:$I$6,2,FALSE)))*L34)+J34)*(1+K34/100*0.25) -> 2527 | P34: Windproof | Q34: 2 | R34: Hunter's Unity
B35: Kurenawi Ougi | C35: Mizutsune Set | D35: Weapon | E35: Sword & Shield | F35: Mizutsune | G35: =IF(ISNA(VLOOKUP(F35,Monster!B:E,4,FALSE)),0,VLOOKUP(F35,Monster!B:E,4,FALSE)) -> 33 | I35: Hana no Nagoriwo | J35: 1138 | K35: 20 | L35: 1156 | M35: Water | O35: =((NOT(ISNA(VLOOKUP(M35,Monster!$H$2:$I$6,2,FALSE)))*L35)+J35)*(1+K35/100*0.25) -> 2408.7 | P35: Artful Dodger | Q35: 1
B36: Teostra's Emblem | C36: Kaiser Set | D36: Weapon | E36: Sword & Shield | F36: Teostra | G36: =IF(ISNA(VLOOKUP(F36,Monster!B:E,4,FALSE)),0,VLOOKUP(F36,Monster!B:E,4,FALSE)) -> 34 | I36: Teostra's Emblem | J36: 1684 | K36: 0 | L36: 502 | M36: Blast | O36: =((NOT(ISNA(VLOOKUP(M36,Monster!$H$2:$I$6,2,FALSE)))*L36)+J36)*(1+K36/100*0.25) -> 1684 | P36: Heroics | Q36: 2 | R36: Hunter's Unity
C37: Aknosom Set | D37: Weapon | E37: Sword & Shield | F37: Aknosom | G37: =IF(ISNA(VLOOKUP(F37,Monster!B:E,4,FALSE)),0,VLOOKUP(F37,Monster!B:E,4,FALSE)) -> 35 | L37: 0 | M37: No Element | O37: =((NOT(ISNA(VLOOKUP(M37,Monster!$H$2:$I$6,2,FALSE)))*L37)+J37)*(1+K37/100*0.25) -> 0 | P37: Lock On | Q37: 1
B38: Sinister Shadekeeper | C38: Sinister Set | D38: Weapon | E38: Sword & Shield | F38: Magnamalo | G38: =IF(ISNA(VLOOKUP(F38,Monster!B:E,4,FALSE)),0,VLOOKUP(F38,Monster!B:E,4,FALSE)) -> 36 | I38: Sinister Sword | J38: 1516 | K38: 0 | L38: 496 | M38: Blast | O38: =((NOT(ISNA(VLOOKUP(M38,Monster!$H$2:$I$6,2,FALSE)))*L38)+J38)*(1+K38/100*0.25) -> 1516 | P38: Partbreaker | Q38: 1
B39: Banned Rajang Club | C39: Golden Set | D39: Weapon | E39: Sword & Shield | F39: Rajang | G39: =IF(ISNA(VLOOKUP(F39,Monster!B:E,4,FALSE)),0,VLOOKUP(F39,Monster!B:E,4,FALSE)) -> 37 | I39: Rajang Club | J39: 1318 | K39: -30 | L39: 1261 | M39: Thunder | O39: =((NOT(ISNA(VLOOKUP(M39,Monster!$H$2:$I$6,2,FALSE)))*L39)+J39)*(1+K39/100*0.25) -> 2385.575 | P39: Partbreaker | Q39: 1
B40: Eradication Vanguard | C40: Nergigante Set | D40: Weapon | E40: Sword & Shield | F40: Nergigante | G40: =IF(ISNA(VLOOKUP(F40,Monster!B:E,4,FALSE)),0,VLOOKUP(F40,Monster!B:E,4,FALSE)) -> 38 | I40: Eradication Vanguard | J40: 1553 | K40: 0 | L40: 974 | M40: Dragon | O40: =((NOT(ISNA(VLOOKUP(M40,Monster!$H$2:$I$6,2,FALSE)))*L40)+J40)*(1+K40/100*0.25) -> 2527 | P40: Partbreaker | Q40: 2 | R40: Hunter's Unity
C41: Lagombi Set | D41: Weapon | E41: Sword & Shield | F41: Lagombi | G41: =IF(ISNA(VLOOKUP(F41,Monster!B:E,4,FALSE)),0,VLOOKUP(F41,Monster!B:E,4,FALSE)) -> 39 | L41: 0 | M41: No Element | O41: =((NOT(ISNA(VLOOKUP(M41,Monster!$H$2:$I$6,2,FALSE)))*L41)+J41)*(1+K41/100*0.25) -> 0 | P41: Lock On | Q41: 1
...

Sheet Weapon_Filtered
A1: id | B1: name | C1: set_name | D1: body_part | E1: body_part_name | F1: monster_name | G1: monster_id | H1: skill_slot | I1: weapon_low_level_alias | J1: weapon_attack | K1: weapon_affinity | L1: weapon_element_value | M1: weapon_element_type | V1: #dup_id | X1: #dup_id
A2: 1 | B2: Steel Knife | C2: Leather Set | D2: Weapon | E2: Sword & Shield | G2: =IF(ISNA(VLOOKUP(F2,Monster!B:E,4,FALSE)),0,VLOOKUP(F2,Monster!B:E,4,FALSE)) -> 0 | I2: Hunter's Knife | J2: 1596 | K2: 0 | L2: 0 | M2: No Element | N2: =((NOT(ISNA(VLOOKUP(M2,Monster!$H$2:$I$6,2,FALSE)))*L2)+J2)*(1+K2/100*0.25) -> 1596 | O2: =M2&" - "&N2 -> No Element - 1596 | P2: Poison Resistance | Q2: 2 | V2: =A2 -> 1 | W2: =L2/(J2+L2) -> 0
A3: 2 | B3: Jagras Garotte | C3: Jagras Set | D3: Weapon | E3: Sword & Shield | F3: Great Jagras | G3: =IF(ISNA(VLOOKUP(F3,Monster!B:E,4,FALSE)),0,VLOOKUP(F3,Monster!B:E,4,FALSE)) -> 1 | I3: Jagras Edge | J3: 1373 | K3: 0 | L3: 607 | M3: Water | N3: =((NOT(ISNA(VLOOKUP(M3,Monster!$H$2:$I$6,2,FALSE)))*L3)+J3)*(1+K3/100*0.25) -> 1980 | O3: =M3&" - "&N3 -> Water - 1980 | P3: Health Boost | Q3: 2 | V3: =A3 -> 2 | W3: =L3/(J3+L3) -> 0.30656566
A4: 3 | B4: Datura Blossom | C4: Pukei Set | D4: Weapon | E4: Sword & Shield | F4: Pukei-Pukei | G4: =IF(ISNA(VLOOKUP(F4,Monster!B:E,4,FALSE)),0,VLOOKUP(F4,Monster!B:E,4,FALSE)) -> 3 | I4: Blooming Knife | J4: 1596 | K4: 0 | L4: 400 | M4: Poison | N4: =((NOT(ISNA(VLOOKUP(M4,Monster!$H$2:$I$6,2,FALSE)))*L4)+J4)*(1+K4/100*0.25) -> 1596 | O4: =M4&" - "&N4 -> Poison - 1596 | P4: Sneak Attack | Q4: 1 | V4: =A4 -> 3 | W4: =L4/(J4+L4) -> 0.2004008
A5: 4 | B5: Laguna Blossom | C5: Coral Pukei Set | D5: Weapon | E5: Sword & Shield | F5: Coral Pukei-Pukei | G5: =IF(ISNA(VLOOKUP(F5,Monster!B:E,4,FALSE)),0,VLOOKUP(F5,Monster!B:E,4,FALSE)) -> 4 | I5: Laguna Blossom | J5: 1221 | K5: 0 | L5: 1142 | M5: Water | N5: =((NOT(ISNA(VLOOKUP(M5,Monster!$H$2:$I$6,2,FALSE)))*L5)+J5)*(1+K5/100*0.25) -> 2363 | O5: =M5&" - "&N5 -> Water - 2363 | P5: Earplugs | Q5: 1 | V5: =A5 -> 4 | W5: =L5/(J5+L5) -> 0.48328396
A6: 5 | B6: Barroth Club | C6: Barroth Set | D6: Weapon | E6: Sword & Shield | F6: Barroth | G6: =IF(ISNA(VLOOKUP(F6,Monster!B:E,4,FALSE)),0,VLOOKUP(F6,Monster!B:E,4,FALSE)) -> 5 | I6: Carapace Edge | J6: 1756 | K6: 0 | L6: 0 | M6: No Element | N6: =((NOT(ISNA(VLOOKUP(M6,Monster!$H$2:$I$6,2,FALSE)))*L6)+J6)*(1+K6/100*0.25) -> 1756 | O6: =M6&" - "&N6 -> No Element - 1756 | P6: Defense Boost | Q6: 2 | V6: =A6 -> 5 | W6: =L6/(J6+L6) -> 0
A7: 6 | B7: Malady's Tabar | C7: Girros Set | D7: Weapon | E7: Sword & Shield | F7: Great Girros | G7: =IF(ISNA(VLOOKUP(F7,Monster!B:E,4,FALSE)),0,VLOOKUP(F7,Monster!B:E,4,FALSE)) -> 6 | I7: Girros Knife | J7: 1596 | K7: 0 | L7: 400 | M7: Paralysis | N7: =((NOT(ISNA(VLOOKUP(M7,Monster!$H$2:$I$6,2,FALSE)))*L7)+J7)*(1+K7/100*0.25) -> 1596 | O7: =M7&" - "&N7 -> Paralysis - 1596 | P7: Sneak Attack | Q7: 1 | V7: =A7 -> 6 | W7: =L7/(J7+L7) -> 0.2004008
A8: 7 | B8: Lightning Nemesis | C8: Kadachi Set | D8: Weapon | E8: Sword & Shield | F8: Tobi-Kadachi | G8: =IF(ISNA(VLOOKUP(F8,Monster!B:E,4,FALSE)),0,VLOOKUP(F8,Monster!B:E,4,FALSE)) -> 7 | I8: Thunder Edge | J8: 1293 | K8: 0 | L8: 910 | M8: Thunder | N8: =((NOT(ISNA(VLOOKUP(M8,Monster!$H$2:$I$6,2,FALSE)))*L8)+J8)*(1+K8/100*0.25) -> 2203 | O8: =M8&" - "&N8 -> Thunder - 2203 | P8: Evade Extender | Q8: 1 | V8: =A8 -> 7 | W8: =L8/(J8+L8) -> 0.41307308
A9: 8 | B9: Lumu Tabar | C9: Paolumu Set | D9: Weapon | E9: Sword & Shield | F9: Paolumu | G9: =IF(ISNA(VLOOKUP(F9,Monster!B:E,4,FALSE)),0,VLOOKUP(F9,Monster!B:E,4,FALSE)) -> 8 | I9: Lumu Knife | J9: 1764 | K9: 0 | L9: 0 | M9: No Element | N9: =((NOT(ISNA(VLOOKUP(M9,Monster!$H$2:$I$6,2,FALSE)))*L9)+J9)*(1+K9/100*0.25) -> 1764 | O9: =M9&" - "&N9 -> No Element - 1764 | P9: Divine Blessing | Q9: 2 | V9: =A9 -> 8 | W9: =L9/(J9+L9) -> 0
A10: 9 | B10: Nyx Tabar | C10: Nightshade Paolumu Set | D10: Weapon | E10: Sword & Shield | F10: Nightshade Paolumu | G10: =IF(ISNA(VLOOKUP(F10,Monster!B:E,4,FALSE)),0,VLOOKUP(F10,Monster!B:E,4,FALSE)) -> 9 | I10: Nyx Tabar | J10: 1756 | K10: 0 | L10: 300 | M10: Sleep | N10: =((NOT(ISNA(VLOOKUP(M10,Monster!$H$2:$I$6,2,FALSE)))*L10)+J10)*(1+K10/100*0.25) -> 1756 | O10: =M10&" - "&N10 -> Sleep - 1756 | P10: Sneak Attack | Q10: 1 | V10: =A10 -> 9 | W10: =L10/(J10+L10) -> 0.1459144
A11: 10 | B11: Rogue Wave | C11: Jyuratodus Set | D11: Weapon | E11: Sword & Shield | F11: Jyuratodus | G11: =IF(ISNA(VLOOKUP(F11,Monster!B:E,4,FALSE)),0,VLOOKUP(F11,Monster!B:E,4,FALSE)) -> 10 | I11: Aqua Messer | J11: 1293 | K11: 0 | L11: 910 | M11: Water | N11: =((NOT(ISNA(VLOOKUP(M11,Monster!$H$2:$I$6,2,FALSE)))*L11)+J11)*(1+K11/100*0.25) -> 2203 | O11: =M11&" - "&N11 -> Water - 2203 | P11: Last Stand | Q11: 1 | V11: =A11 -> 10 | W11: =L11/(J11+L11) -> 0.41307308
A12: 11 | B12: Flammensucher | C12: Anjanath Set | D12: Weapon | E12: Sword & Shield | F12: Anjanath | G12: =IF(ISNA(VLOOKUP(F12,Monster!B:E,4,FALSE)),0,VLOOKUP(F12,Monster!B:E,4,FALSE)) -> 11 | I12: Blazing Edge | J12: 1293 | K12: 0 | L12: 910 | M12: Fire | N12: =((NOT(ISNA(VLOOKUP(M12,Monster!$H$2:$I$6,2,FALSE)))*L12)+J12)*(1+K12/100*0.25) -> 2203 | O12: =M12&" - "&N12 -> Fire - 2203 | P12: Rising Tide | Q12: 1 | V12: =A12 -> 11 | W12: =L12/(J12+L12) -> 0.41307308
A13: 12 | B13: Donnersieger | C13: Fulgur Set | D13: Weapon | E13: Sword & Shield | F13: Fulgur Anjanath | G13: =IF(ISNA(VLOOKUP(F13,Monster!B:E,4,FALSE)),0,VLOOKUP(F13,Monster!B:E,4,FALSE)) -> 12 | I13: Donnersieger | J13: 1197 | K13: 20 | L13: 1154 | M13: Thunder | N13: =((NOT(ISNA(VLOOKUP(M13,Monster!$H$2:$I$6,2,FALSE)))*L13)+J13)*(1+K13/100*0.25) -> 2468.55 | O13: =M13&" - "&N13 -> Thunder - 2468.55 | P13: Critical Element | Q13: 1 | V13: =A13 -> 12 | W13: =L13/(J13+L13) -> 0.49085496
A14: 13 | B14: Queen Rapier | C14: Rathian Set | D14: Weapon | E14: Sword & Shield | F14: Rathian | G14: =IF(ISNA(VLOOKUP(F14,Monster!B:E,4,FALSE)),0,VLOOKUP(F14,Monster!B:E,4,FALSE)) -> 13 | I14: Princess Rapier | J14: 1516 | K14: 0 | L14: 496 | M14: Poison | N14: =((NOT(ISNA(VLOOKUP(M14,Monster!$H$2:$I$6,2,FALSE)))*L14)+J14)*(1+K14/100*0.25) -> 1516 | O14: =M14&" - "&N14 -> Poison - 1516 | P14: Health Boost | Q14: 2 | V14: =A14 -> 13 | W14: =L14/(J14+L14) -> 0.24652087
... A25: 24 | B25: Painful Razor | C25: Khezu Set | D25: Weapon | E25: Sword & Shield | F25: Khezu | G25: =IF(ISNA(VLOOKUP(F25,Monster!B:E,4,FALSE)),0,VLOOKUP(F25,Monster!B:E,4,FALSE)) -> 31 | I25: Khezu Razor | J25: 1194 | K25: 20 | L25: 913 | M25: Thunder | N25: =((NOT(ISNA(VLOOKUP(M25,Monster!$H$2:$I$6,2,FALSE)))*L25)+J25)*(1+K25/100*0.25) -> 2212.35 | O25: =M25&" - "&N25 -> Thunder - 2212.35 | P25: Peak Performance | Q25: 1 | V25: =A25 -> 24 | W25: =L25/(J25+L25) -> 0.43331751
A26: 25 | B26: Daora's Razor | C26: Kushala Set | D26: Weapon | E26: Sword & Shield | F26: Kushala Daora | G26: =IF(ISNA(VLOOKUP(F26,Monster!B:E,4,FALSE)),0,VLOOKUP(F26,Monster!B:E,4,FALSE)) -> 32 | I26: Daora's Razor | J26: 1553 | K26: 0 | L26: 974 | M26: Ice | N26: =((NOT(ISNA(VLOOKUP(M26,Monster!$H$2:$I$6,2,FALSE)))*L26)+J26)*(1+K26/100*0.25) -> 2527 | O26: =M26&" - "&N26 -> Ice - 2527 | P26: Windproof | Q26: 2 | R26: Hunter's Unity | V26: =A26 -> 25 | W26: =L26/(J26+L26) -> 0.38543728
A27: 26 | B27: Kurenawi Ougi | C27: Mizutsune Set | D27: Weapon | E27: Sword & Shield | F27: Mizutsune | G27: =IF(ISNA(VLOOKUP(F27,Monster!B:E,4,FALSE)),0,VLOOKUP(F27,Monster!B:E,4,FALSE)) -> 33 | I27: Hana no Nagoriwo | J27: 1138 | K27: 20 | L27: 1156 | M27: Water | N27: =((NOT(ISNA(VLOOKUP(M27,Monster!$H$2:$I$6,2,FALSE)))*L27)+J27)*(1+K27/100*0.25) -> 2408.7 | O27: =M27&" - "&N27 -> Water - 2408.7 | P27: Artful Dodger | Q27: 1 | V27: =A27 -> 26 | W27: =L27/(J27+L27) -> 0.50392328
A28: 27 | B28: Teostra's Emblem | C28: Kaiser Set | D28: Weapon | E28: Sword & Shield | F28: Teostra | G28: =IF(ISNA(VLOOKUP(F28,Monster!B:E,4,FALSE)),0,VLOOKUP(F28,Monster!B:E,4,FALSE)) -> 34 | I28: Teostra's Emblem | J28: 1684 | K28: 0 | L28: 502 | M28: Blast | N28: =((NOT(ISNA(VLOOKUP(M28,Monster!$H$2:$I$6,2,FALSE)))*L28)+J28)*(1+K28/100*0.25) -> 1684 | O28: =M28&" - "&N28 -> Blast - 1684 | P28: Heroics | Q28: 2 | R28: Hunter's Unity | V28: =A28 -> 27 | W28: =L28/(J28+L28) -> 0.22964318
A29: 28 | B29: Sinister Shadekeeper | C29: Sinister Set | D29: Weapon | E29: Sword & Shield | F29: Magnamalo | G29: =IF(ISNA(VLOOKUP(F29,Monster!B:E,4,FALSE)),0,VLOOKUP(F29,Monster!B:E,4,FALSE)) -> 36 | I29: Sinister Sword | J29: 1516 | K29: 0 | L29: 496 | M29: Blast | N29: =((NOT(ISNA(VLOOKUP(M29,Monster!$H$2:$I$6,2,FALSE)))*L29)+J29)*(1+K29/100*0.25) -> 1516 | O29: =M29&" - "&N29 -> Blast - 1516 | P29: Partbreaker | Q29: 1 | V29: =A29 -> 28 | W29: =L29/(J29+L29) -> 0.24652087
A30: 29 | B30: Banned Rajang Club | C30: Golden Set | D30: Weapon | E30: Sword & Shield | F30: Rajang | G30: =IF(ISNA(VLOOKUP(F30,Monster!B:E,4,FALSE)),0,VLOOKUP(F30,Monster!B:E,4,FALSE)) -> 37 | I30: Rajang Club | J30: 1318 | K30: -30 | L30: 1261 | M30: Thunder | N30: =((NOT(ISNA(VLOOKUP(M30,Monster!$H$2:$I$6,2,FALSE)))*L30)+J30)*(1+K30/100*0.25) -> 2385.575 | O30: =M30&" - "&N30 -> Thunder - 2385.575 | P30: Partbreaker | Q30: 1 | V30: =A30 -> 29 | W30: =L30/(J30+L30) -> 0.48894921
A31: 30 | B31: Eradication Vanguard | C31: Nergigante Set | D31: Weapon | E31: Sword & Shield | F31: Nergigante | G31: =IF(ISNA(VLOOKUP(F31,Monster!B:E,4,FALSE)),0,VLOOKUP(F31,Monster!B:E,4,FALSE)) -> 38 | I31: Eradication Vanguard | J31: 1553 | K31: 0 | L31: 974 | M31: Dragon | N31: =((NOT(ISNA(VLOOKUP(M31,Monster!$H$2:$I$6,2,FALSE)))*L31)+J31)*(1+K31/100*0.25) -> 2527 | O31: =M31&" - "&N31 -> Dragon - 2527 | P31: Partbreaker | Q31: 2 | R31: Hunter's Unity | V31: =A31 -> 30 | W31: =L31/(J31+L31) -> 0.38543728
A32: 31 | B32: Rex Talon+ | C32: Tigrex Set | D32: Weapon | E32: Sword & Shield | F32: Tigrex | G32: =IF(ISNA(VLOOKUP(F32,Monster!B:E,4,FALSE)),0,VLOOKUP(F32,Monster!B:E,4,FALSE)) -> 42 | I32: Rex Talon | J32: 2198 | K32: -40 | L32: 0 | M32: No Element | N32: =((NOT(ISNA(VLOOKUP(M32,Monster!$H$2:$I$6,2,FALSE)))*L32)+J32)*(1+K32/100*0.25) -> 1978.2 | O32: =M32&" - "&N32 -> No Element - 1978.2 | P32: Critical Ferocity | Q32: 1 | V32: =A32 -> 31 | W32: =L32/(J32+L32) -> 0
A33: 32 | B33: Stonebite | C33: Rex Roar Set | D33: Weapon | E33: Sword & Shield | F33: Brute Tigrex | G33: =IF(ISNA(VLOOKUP(F33,Monster!B:E,4,FALSE)),0,VLOOKUP(F33,Monster!B:E,4,FALSE)) -> 43 | I33: Accursed Claw | J33: 2198 | K33: -10 | L33: 0 | M33: No Element | N33: =((NOT(ISNA(VLOOKUP(M33,Monster!$H$2:$I$6,2,FALSE)))*L33)+J33)*(1+K33/100*0.25) -> 2143.05 | O33: =M33&" - "&N33 -> No Element - 2143.05 | P33: Aggressive Dodger | Q33: 5 | V33: =A33 -> 32 | W33: =L33/(J33+L33) -> 0
A34: 33 | B34: Fulminator | C34: Kirin Set | D34: Weapon | E34: Sword & Shield | F34: Kirin | G34: =IF(ISNA(VLOOKUP(F34,Monster!B:E,4,FALSE)),0,VLOOKUP(F34,Monster!B:E,4,FALSE)) -> 44 | I34: Fulminator | J34: 1205 | K34: 0 | L34: 1305 | M34: Thunder | N34: =((NOT(ISNA(VLOOKUP(M34,Monster!$H$2:$I$6,2,FALSE)))*L34)+J34)*(1+K34/100*0.25) -> 2510 | O34: =M34&" - "&N34 -> Thunder - 2510 | P34: Latent Power | Q34: 1 | R34: Hunter's Unity | V34: =A34 -> 33 | W34: =L34/(J34+L34) -> 0.51992032
A35: 34 | B35: Shrouded Katalo | C35: Chatacabra Set | D35: Weapon | E35: Sword & Shield | F35: Chatacabra | G35: =IF(ISNA(VLOOKUP(F35,Monster!B:E,4,FALSE)),0,VLOOKUP(F35,Monster!B:E,4,FALSE)) -> 46 | I35: Chata Club | J35: 1834 | K35: 10 | L35: 0 | M35: No Element | N35: =((NOT(ISNA(VLOOKUP(M35,Monster!$H$2:$I$6,2,FALSE)))*L35)+J35)*(1+K35/100*0.25) -> 1879.85 | O35: =M35&" - "&N35 -> No Element - 1879.85 | P35: Litheness | Q35: 1 | V35: =A35 -> 34 | W35: =L35/(J35+L35) -> 0
A36: 35 | B36: Glavenus Razor | C36: Glavenus Set | D36: Weapon | E36: Sword & Shield | F36: Glavenus | G36: =IF(ISNA(VLOOKUP(F36,Monster!B:E,4,FALSE)),0,VLOOKUP(F36,Monster!B:E,4,FALSE)) -> 48 | I36: Glavenus Razor | J36: 1318 | K36: -30 | L36: 1261 | M36: Fire | N36: =((NOT(ISNA(VLOOKUP(M36,Monster!$H$2:$I$6,2,FALSE)))*L36)+J36)*(1+K36/100*0.25) -> 2385.575 | O36: =M36&" - "&N36 -> Fire - 2385.575 | P36: Critical Ferocity | Q36: 1 | V36: =A36 -> 35 | W36: =L36/(J36+L36) -> 0.48894921
A37: 36 | B37: Dirty Marquis | C37: Wroggi Set | D37: Weapon | E37: Sword & Shield | F37: Great Wroggi | G37: =IF(ISNA(VLOOKUP(F37,Monster!B:E,4,FALSE)),0,VLOOKUP(F37,Monster!B:E,4,FALSE)) -> 50 | I37: Dirty Baron | J37: 1647 | K37: 10 | L37: 307 | M37: Poison | N37: =((NOT(ISNA(VLOOKUP(M37,Monster!$H$2:$I$6,2,FALSE)))*L37)+J37)*(1+K37/100*0.25) -> 1688.175 | O37: =M37&" - "&N37 -> Poison - 1688.175 | P37: Lock On | Q37: 1 | V37: =A37 -> 36 | W37: =L37/(J37+L37) -> 0.15711361
A38: 37 | B38: Shaucha Pureblade | C38: Bishaten Set | D38: Weapon | E38: Sword & Shield | F38: Bishaten | G38: =IF(ISNA(VLOOKUP(F38,Monster!B:E,4,FALSE)),0,VLOOKUP(F38,Monster!B:E,4,FALSE)) -> 51 | I38: Exorcising Sword | J38: 1764 | K38: 0 | L38: 0 | M38: No Element | N38: =((NOT(ISNA(VLOOKUP(M38,Monster!$H$2:$I$6,2,FALSE)))*L38)+J38)*(1+K38/100*0.25) -> 1764 | O38: =M38&" - "&N38 -> No Element - 1764 | P38: Shared Sword | Q38: 2 | V38: =A38 -> 37 | W38: =L38/(J38+L38) -> 0
A39: 38 | B39: Hidden Edge | C39: Nargacuga Set | D39: Weapon | E39: Sword & Shield | F39: Nargacuga | G39: =IF(ISNA(VLOOKUP(F39,Monster!B:E,4,FALSE)),0,VLOOKUP(F39,Monster!B:E,4,FALSE)) -> 53 | I39: Hidden Edge | J39: 1738 | K39: 40 | L39: 0 | M39: No Element | N39: =((NOT(ISNA(VLOOKUP(M39,Monster!$H$2:$I$6,2,FALSE)))*L39)+J39)*(1+K39/100*0.25) -> 1911.8 | O39: =M39&" - "&N39 -> No Element - 1911.8 | P39: Resuscitate | Q39: 2 | V39: =A39 -> 38 | W39: =L39/(J39+L39) -> 0
A40: 39 | B40: Hydros Discus | C40: Tentacle Set | D40: Weapon | E40: Sword & Shield | F40: Namielle | G40: =IF(ISNA(VLOOKUP(F40,Monster!B:E,4,FALSE)),0,VLOOKUP(F40,Monster!B:E,4,FALSE)) -> 54 | I40: Hydros Discus | J40: 1328 | K40: 20 | L40: 1074 | M40: Water | N40: =((NOT(ISNA(VLOOKUP(M40,Monster!$H$2:$I$6,2,FALSE)))*L40)+J40)*(1+K40/100*0.25) -> 2522.1 | O40: =M40&" - "&N40 -> Water - 2522.1 | P40: Weakness Exploit | Q40: 1 | R40: Hunter's Unity | V40: =A40 -> 39 | W40: =L40/(J40+L40) -> 0.44712739
A41: 40 | B41: Golm Sword | C41: Garangolm Set | D41: Weapon | E41: Sword & Shield | F41: Garangolm | G41: =IF(ISNA(VLOOKUP(F41,Monster!B:E,4,FALSE)),0,VLOOKUP(F41,Monster!B:E,4,FALSE)) -> 55 | I41: Golm Sword | J41: 1979 | K41: 0 | L41: 0 | M41: No Element | N41: =((NOT(ISNA(VLOOKUP(M41,Monster!$H$2:$I$6,2,FALSE)))*L41)+J41)*(1+K41/100*0.25) -> 1979 | O41: =M41&" - "&N41 -> No Element - 1979 | P41: Reckless | Q41: 1 | V41: =A41 -> 40 | W41: =L41/(J41+L41) -> 0
A42: 41 | B42: Frostmoon Hatchet | C42: Lunagaron Set | D42: Weapon | E42: Sword & Shield | F42: Lunagaron | G42: =IF(ISNA(VLOOKUP(F42,Monster!B:E,4,FALSE)),0,VLOOKUP(F42,Monster!B:E,4,FALSE)) -> 56 | I42: Frostmoon Hatchet | J42: 1020 | K42: 0 | L42: 1173 | M42: Ice | N42: =((NOT(ISNA(VLOOKUP(M42,Monster!$H$2:$I$6,2,FALSE)))*L42)+J42)*(1+K42/100*0.25) -> 2193 | O42: =M42&" - "&N42 -> Ice - 2193 | P42: Vital Ice | Q42: 1 | V42: =A42 -> 41 | W42: =L42/(J42+L42) -> 0.53488372
A43: 42 | B43: Rosenmesser | C43: Espinas Set | D43: Weapon | E43: Sword & Shield | F43: Espinas | G43: =IF(ISNA(VLOOKUP(F43,Monster!B:E,4,FALSE)),0,VLOOKUP(F43,Monster!B:E,4,FALSE)) -> 57 | I43: Rosenmesser | J43: 1197 | K43: 20 | L43: 1154 | M43: Fire | N43: =((NOT(ISNA(VLOOKUP(M43,Monster!$H$2:$I$6,2,FALSE)))*L43)+J43)*(1+K43/100*0.25) -> 2468.55 | O43: =M43&" - "&N43 -> Fire - 2468.55 | P43: Special Partbreaker | Q43: 2 | V43: =A43 -> 42 | W43: =L43/(J43+L43) -> 0.49085496
A44: 43 | B44: Bloodlust Blade | C44: Malzeno Set | D44: Weapon | E44: Sword & Shield | F44: Malzeno | G44: =IF(ISNA(VLOOKUP(F44,Monster!B:E,4,FALSE)),0,VLOOKUP(F44,Monster!B:E,4,FALSE)) -> 58 | I44: Bloodlust Blade | J44: 1205 | K44: 0 | L44: 1305 | M44: Dragon | N44: =((NOT(ISNA(VLOOKUP(M44,Monster!$H$2:$I$6,2,FALSE)))*L44)+J44)*(1+K44/100*0.25) -> 2510 | O44: =M44&" - "&N44 -> Dragon - 2510 | P44: Vital Dragon | Q44: 1 | R44: Hunter's Unity | V44: =A44 -> 43 | W44: =L44/(J44+L44) -> 0.51992032
A45: 44 | B45: Chief Kukri | C45: Bone Set | D45: Weapon | E45: Sword & Shield | G45: =IF(ISNA(VLOOKUP(F45,Monster!B:E,4,FALSE)),0,VLOOKUP(F45,Monster!B:E,4,FALSE)) -> 0 | I45: Bone Kukri | J45: 1596 | K45: 0 | L45: 0 | M45: No Element | N45: =((NOT(ISNA(VLOOKUP(M45,Monster!$H$2:$I$6,2,FALSE)))*L45)+J45)*(1+K45/100*0.25) -> 1596 | O45: =M45&" - "&N45 -> No Element - 1596 | P45: Concentration | Q45: 1 | V45: =A45 -> 44 | W45: =L45/(J45+L45) -> 0
A46: 45 | B46: MrBeast Sword & Shield | C46: MrBeast Set | D46: Weapon | E46: Sword & Shield | G46: =IF(ISNA(VLOOKUP(F46,Monster!B:E,4,FALSE)),0,VLOOKUP(F46,Monster!B:E,4,FALSE)) -> 0 | I46: MrBeast Sword & Shield | J46: 1821 | K46: 30 | L46: 0 | M46: No Element | N46: =((NOT(ISNA(VLOOKUP(M46,Monster!$H$2:$I$6,2,FALSE)))*L46)+J46)*(1+K46/100*0.25) -> 1957.575 | O46: =M46&" - "&N46 -> No Element - 1957.575 | P46: MrBeast Challenge! | Q46: 1 | V46: =A46 -> 45 | W46: =L46/(J46+L46) -> 0
A47: 46 | B47: Esperanza Sword | C47: Hope Set | D47: Weapon | E47: Sword & Shield | G47: =IF(ISNA(VLOOKUP(F47,Monster!B:E,4,FALSE)),0,VLOOKUP(F47,Monster!B:E,4,FALSE)) -> 0 | I47: Hope Sword | J47: 1878 | K47: 0 | L47: 0 | M47: No Element | N47: =((NOT(ISNA(VLOOKUP(M47,Monster!$H$2:$I$6,2,FALSE)))*L47)+J47)*(1+K47/100*0.25) -> 1878 | O47: =M47&" - "&N47 -> No Element - 1878 | P47: Lock On | Q47: 1 | V47: =A47 -> 46 | W47: =L47/(J47+L47) -> 0
A48: 47 | B48: Dual Slicers | C48: Leather Set | D48: Weapon | E48: Dual Blades | G48: =IF(ISNA(VLOOKUP(F48,Monster!B:E,4,FALSE)),0,VLOOKUP(F48,Monster!B:E,4,FALSE)) -> 0 | I48: Matched Slicers | J48: 1596 | K48: 0 | L48: 0 | M48: No Element | N48: =((NOT(ISNA(VLOOKUP(M48,Monster!$H$2:$I$6,2,FALSE)))*L48)+J48)*(1+K48/100*0.25) -> 1596 | O48: =M48&" - "&N48 -> No Element - 1596 | P48: Poison Resistance | Q48: 2 | V48: =A48 -> 47 | W48: =L48/(J48+L48) -> 0
