Workbook

Sheet Picker
A1: Monster Hunter Now — Armour Picker
A2: Only the shaded cells are yours to edit. Everything else is a formula.
A3: 1. Skills you want
A4: Wanted skill | B4: In build | C4: Cap
B5: =IF(OR($A5="",$A5="(none)"),"",IFERROR(INDEX(Calc!$B$2:$B$132,MATCH($A5,Calc!$A$2:$A$132,0)),0)) | C5: =IF(OR($A5="",$A5="(none)"),"",IFERROR(INDEX(Skills!$C$2:$C$132,MATCH($A5,Skills!$A$2:$A$132,0)),""))
B6: =IF(OR($A6="",$A6="(none)"),"",IFERROR(INDEX(Calc!$B$2:$B$132,MATCH($A6,Calc!$A$2:$A$132,0)),0)) | C6: =IF(OR($A6="",$A6="(none)"),"",IFERROR(INDEX(Skills!$C$2:$C$132,MATCH($A6,Skills!$A$2:$A$132,0)),""))
B7: =IF(OR($A7="",$A7="(none)"),"",IFERROR(INDEX(Calc!$B$2:$B$132,MATCH($A7,Calc!$A$2:$A$132,0)),0)) | C7: =IF(OR($A7="",$A7="(none)"),"",IFERROR(INDEX(Skills!$C$2:$C$132,MATCH($A7,Skills!$A$2:$A$132,0)),""))
B8: =IF(OR($A8="",$A8="(none)"),"",IFERROR(INDEX(Calc!$B$2:$B$132,MATCH($A8,Calc!$A$2:$A$132,0)),0)) | C8: =IF(OR($A8="",$A8="(none)"),"",IFERROR(INDEX(Skills!$C$2:$C$132,MATCH($A8,Skills!$A$2:$A$132,0)),""))
B9: =IF(OR($A9="",$A9="(none)"),"",IFERROR(INDEX(Calc!$B$2:$B$132,MATCH($A9,Calc!$A$2:$A$132,0)),0)) | C9: =IF(OR($A9="",$A9="(none)"),"",IFERROR(INDEX(Skills!$C$2:$C$132,MATCH($A9,Skills!$A$2:$A$132,0)),""))
A10: Ignore all wanted skills → | B10: No | C10: =IF($B$10="Yes","all skills ignored — showing every piece","")
A12: 2. Matching armour (best matches first)
A13: Head | B13: Chest | C13: Arms | D13: Waist | E13: Legs
A14: =IFERROR(INDEX(Armour!$H$2:$H$346,MATCH(A$13&"#"&1,Armour!$K$2:$K$346,0)),"") | B14: =IFERROR(INDEX(Armour!$H$2:$H$346,MATCH(B$13&"#"&1,Armour!$K$2:$K$346,0)),"") | C14: =IFERROR(INDEX(Armour!$H$2:$H$346,MATCH(C$13&"#"&1,Armour!$K$2:$K$346,0)),"") | D14: =IFERROR(INDEX(Armour!$H$2:$H$346,MATCH(D$13&"#"&1,Armour!$K$2:$K$346,0)),"") | E14: =IFERROR(INDEX(Armour!$H$2:$H$346,MATCH(E$13&"#"&1,Armour!$K$2:$K$346,0)),"")
A15: =IFERROR(INDEX(Armour!$H$2:$H$346,MATCH(A$13&"#"&2,Armour!$K$2:$K$346,0)),"") | B15: =IFERROR(INDEX(Armour!$H$2:$H$346,MATCH(B$13&"#"&2,Armour!$K$2:$K$346,0)),"") | C15: =IFERROR(INDEX(Armour!$H$2:$H$346,MATCH(C$13&"#"&2,Armour!$K$2:$K$346,0)),"") | D15: =IFERROR(INDEX(Armour!$H$2:$H$346,MATCH(D$13&"#"&2,Armour!$K$2:$K$346,0)),"") | E15: =IFERROR(INDEX(Armour!$H$2:$H$346,MATCH(E$13&"#"&2,Armour!$K$2:$K$346,0)),"")
A16: =IFERROR(INDEX(Armour!$H$2:$H$346,MATCH(A$13&"#"&3,Armour!$K$2:$K$346,0)),"") | B16: =IFERROR(INDEX(Armour!$H$2:$H$346,MATCH(B$13&"#"&3,Armour!$K$2:$K$346,0)),"") | C16: =IFERROR(INDEX(Armour!$H$2:$H$346,MATCH(C$13&"#"&3,Armour!$K$2:$K$346,0)),"") | D16: =IFERROR(INDEX(Armour!$H$2:$H$346,MATCH(D$13&"#"&3,Armour!$K$2:$K$346,0)),"") | E16: =IFERROR(INDEX(Armour!$H$2:$H$346,MATCH(E$13&"#"&3,Armour!$K$2:$K$346,0)),"")
A17: =IFERROR(INDEX(Armour!$H$2:$H$346,MATCH(A$13&"#"&4,Armour!$K$2:$K$346,0)),"") | B17: =IFERROR(INDEX(Armour!$H$2:$H$346,MATCH(B$13&"#"&4,Armour!$K$2:$K$346,0)),"") | C17: =IFERROR(INDEX(Armour!$H$2:$H$346,MATCH(C$13&"#"&4,Armour!$K$2:$K$346,0)),"") | D17: =IFERROR(INDEX(Armour!$H$2:$H$346,MATCH(D$13&"#"&4,Armour!$K$2:$K$346,0)),"") | E17: =IFERROR(INDEX(Armour!$H$2:$H$346,MATCH(E$13&"#"&4,Armour!$K$2:$K$346,0)),"")
A18: =IFERROR(INDEX(Armour!$H$2:$H$346,MATCH(A$13&"#"&5,Armour!$K$2:$K$346,0)),"") | B18: =IFERROR(INDEX(Armour!$H$2:$H$346,MATCH(B$13&"#"&5,Armour!$K$2:$K$346,0)),"") | C18: =IFERROR(INDEX(Armour!$H$2:$H$346,MATCH(C$13&"#"&5,Armour!$K$2:$K$346,0)),"") | D18: =IFERROR(INDEX(Armour!$H$2:$H$346,MATCH(D$13&"#"&5,Armour!$K$2:$K$346,0)),"") | E18: =IFERROR(INDEX(Armour!$H$2:$H$346,MATCH(E$13&"#"&5,Armour!$K$2:$K$346,0)),"")
A19: =IFERROR(INDEX(Armour!$H$2:$H$346,MATCH(A$13&"#"&6,Armour!$K$2:$K$346,0)),"") | B19: =IFERROR(INDEX(Armour!$H$2:$H$346,MATCH(B$13&"#"&6,Armour!$K$2:$K$346,0)),"") | C19: =IFERROR(INDEX(Armour!$H$2:$H$346,MATCH(C$13&"#"&6,Armour!$K$2:$K$346,0)),"") | D19: =IFERROR(INDEX(Armour!$H$2:$H$346,MATCH(D$13&"#"&6,Armour!$K$2:$K$346,0)),"") | E19: =IFERROR(INDEX(Armour!$H$2:$H$346,MATCH(E$13&"#"&6,Armour!$K$2:$K$346,0)),"")
A20: =IFERROR(INDEX(Armour!$H$2:$H$346,MATCH(A$13&"#"&7,Armour!$K$2:$K$346,0)),"") | B20: =IFERROR(INDEX(Armour!$H$2:$H$346,MATCH(B$13&"#"&7,Armour!$K$2:$K$346,0)),"") | C20: =IFERROR(INDEX(Armour!$H$2:$H$346,MATCH(C$13&"#"&7,Armour!$K$2:$K$346,0)),"") | D20: =IFERROR(INDEX(Armour!$H$2:$H$346,MATCH(D$13&"#"&7,Armour!$K$2:$K$346,0)),"") | E20: =IFERROR(INDEX(Armour!$H$2:$H$346,MATCH(E$13&"#"&7,Armour!$K$2:$K$346,0)),"")
A21: =IFERROR(INDEX(Armour!$H$2:$H$346,MATCH(A$13&"#"&8,Armour!$K$2:$K$346,0)),"") | B21: =IFERROR(INDEX(Armour!$H$2:$H$346,MATCH(B$13&"#"&8,Armour!$K$2:$K$346,0)),"") | C21: =IFERROR(INDEX(Armour!$H$2:$H$346,MATCH(C$13&"#"&8,Armour!$K$2:$K$346,0)),"") | D21: =IFERROR(INDEX(Armour!$H$2:$H$346,MATCH(D$13&"#"&8,Armour!$K$2:$K$346,0)),"") | E21: =IFERROR(INDEX(Armour!$H$2:$H$346,MATCH(E$13&"#"&8,Armour!$K$2:$K$346,0)),"")
A22: =IFERROR(INDEX(Armour!$H$2:$H$346,MATCH(A$13&"#"&9,Armour!$K$2:$K$346,0)),"") | B22: =IFERROR(INDEX(Armour!$H$2:$H$346,MATCH(B$13&"#"&9,Armour!$K$2:$K$346,0)),"") | C22: =IFERROR(INDEX(Armour!$H$2:$H$346,MATCH(C$13&"#"&9,Armour!$K$2:$K$346,0)),"") | D22: =IFERROR(INDEX(Armour!$H$2:$H$346,MATCH(D$13&"#"&9,Armour!$K$2:$K$346,0)),"") | E22: =IFERROR(INDEX(Armour!$H$2:$H$346,MATCH(E$13&"#"&9,Armour!$K$2:$K$346,0)),"")
A23: =IFERROR(INDEX(Armour!$H$2:$H$346,MATCH(A$13&"#"&10,Armour!$K$2:$K$346,0)),"") | B23: =IFERROR(INDEX(Armour!$H$2:$H$346,MATCH(B$13&"#"&10,Armour!$K$2:$K$346,0)),"") | C23: =IFERROR(INDEX(Armour!$H$2:$H$346,MATCH(C$13&"#"&10,Armour!$K$2:$K$346,0)),"") | D23: =IFERROR(INDEX(Armour!$H$2:$H$346,MATCH(D$13&"#"&10,Armour!$K$2:$K$346,0)),"") | E23: =IFERROR(INDEX(Armour!$H$2:$H$346,MATCH(E$13&"#"&10,Armour!$K$2:$K$346,0)),"")
A24: =IFERROR(INDEX(Armour!$H$2:$H$346,MATCH(A$13&"#"&11,Armour!$K$2:$K$346,0)),"") | B24: =IFERROR(INDEX(Armour!$H$2:$H$346,MATCH(B$13&"#"&11,Armour!$K$2:$K$346,0)),"") | C24: =IFERROR(INDEX(Armour!$H$2:$H$346,MATCH(C$13&"#"&11,Armour!$K$2:$K$346,0)),"") | D24: =IFERROR(INDEX(Armour!$H$2:$H$346,MATCH(D$13&"#"&11,Armour!$K$2:$K$346,0)),"") | E24: =IFERROR(INDEX(Armour!$H$2:$H$346,MATCH(E$13&"#"&11,Armour!$K$2:$K$346,0)),"")
A25: =IFERROR(INDEX(Armour!$H$2:$H$346,MATCH(A$13&"#"&12,Armour!$K$2:$K$346,0)),"") | B25: =IFERROR(INDEX(Armour!$H$2:$H$346,MATCH(B$13&"#"&12,Armour!$K$2:$K$346,0)),"") | C25: =IFERROR(INDEX(Armour!$H$2:$H$346,MATCH(C$13&"#"&12,Armour!$K$2:$K$346,0)),"") | D25: =IFERROR(INDEX(Armour!$H$2:$H$346,MATCH(D$13&"#"&12,Armour!$K$2:$K$346,0)),"") | E25: =IFERROR(INDEX(Armour!$H$2:$H$346,MATCH(E$13&"#"&12,Armour!$K$2:$K$346,0)),"")
A26: =IFERROR(INDEX(Armour!$H$2:$H$346,MATCH(A$13&"#"&13,Armour!$K$2:$K$346,0)),"") | B26: =IFERROR(INDEX(Armour!$H$2:$H$346,MATCH(B$13&"#"&13,Armour!$K$2:$K$346,0)),"") | C26: =IFERROR(INDEX(Armour!$H$2:$H$346,MATCH(C$13&"#"&13,Armour!$K$2:$K$346,0)),"") | D26: =IFERROR(INDEX(Armour!$H$2:$H$346,MATCH(D$13&"#"&13,Armour!$K$2:$K$346,0)),"") | E26: =IFERROR(INDEX(Armour!$H$2:$H$346,MATCH(E$13&"#"&13,Armour!$K$2:$K$346,0)),"")
A27: =IFERROR(INDEX(Armour!$H$2:$H$346,MATCH(A$13&"#"&14,Armour!$K$2:$K$346,0)),"") | B27: =IFERROR(INDEX(Armour!$H$2:$H$346,MATCH(B$13&"#"&14,Armour!$K$2:$K$346,0)),"") | C27: =IFERROR(INDEX(Armour!$H$2:$H$346,MATCH(C$13&"#"&14,Armour!$K$2:$K$346,0)),"") | D27: =IFERROR(INDEX(Armour!$H$2:$H$346,MATCH(D$13&"#"&14,Armour!$K$2:$K$346,0)),"") | E27: =IFERROR(INDEX(Armour!$H$2:$H$346,MATCH(E$13&"#"&14,Armour!$K$2:$K$346,0)),"")
A28: =IFERROR(INDEX(Armour!$H$2:$H$346,MATCH(A$13&"#"&15,Armour!$K$2:$K$346,0)),"") | B28: =IFERROR(INDEX(Armour!$H$2:$H$346,MATCH(B$13&"#"&15,Armour!$K$2:$K$346,0)),"") | C28: =IFERROR(INDEX(Armour!$H$2:$H$346,MATCH(C$13&"#"&15,Armour!$K$2:$K$346,0)),"") | D28: =IFERROR(INDEX(Armour!$H$2:$H$346,MATCH(D$13&"#"&15,Armour!$K$2:$K$346,0)),"") | E28: =IFERROR(INDEX(Armour!$H$2:$H$346,MATCH(E$13&"#"&15,Armour!$K$2:$K$346,0)),"")
A29: =IFERROR(INDEX(Armour!$H$2:$H$346,MATCH(A$13&"#"&16,Armour!$K$2:$K$346,0)),"") | B29: =IFERROR(INDEX(Armour!$H$2:$H$346,MATCH(B$13&"#"&16,Armour!$K$2:$K$346,0)),"") | C29: =IFERROR(INDEX(Armour!$H$2:$H$346,MATCH(C$13&"#"&16,Armour!$K$2:$K$346,0)),"") | D29: =IFERROR(INDEX(Armour!$H$2:$H$346,MATCH(D$13&"#"&16,Armour!$K$2:$K$346,0)),"") | E29: =IFERROR(INDEX(Armour!$H$2:$H$346,MATCH(E$13&"#"&16,Armour!$K$2:$K$346,0)),"")
A30: =IFERROR(INDEX(Armour!$H$2:$H$346,MATCH(A$13&"#"&17,Armour!$K$2:$K$346,0)),"") | B30: =IFERROR(INDEX(Armour!$H$2:$H$346,MATCH(B$13&"#"&17,Armour!$K$2:$K$346,0)),"") | C30: =IFERROR(INDEX(Armour!$H$2:$H$346,MATCH(C$13&"#"&17,Armour!$K$2:$K$346,0)),"") | D30: =IFERROR(INDEX(Armour!$H$2:$H$346,MATCH(D$13&"#"&17,Armour!$K$2:$K$346,0)),"") | E30: =IFERROR(INDEX(Armour!$H$2:$H$346,MATCH(E$13&"#"&17,Armour!$K$2:$K$346,0)),"")
A31: =IFERROR(INDEX(Armour!$H$2:$H$346,MATCH(A$13&"#"&18,Armour!$K$2:$K$346,0)),"") | B31: =IFERROR(INDEX(Armour!$H$2:$H$346,MATCH(B$13&"#"&18,Armour!$K$2:$K$346,0)),"") | C31: =IFERROR(INDEX(Armour!$H$2:$H$346,MATCH(C$13&"#"&18,Armour!$K$2:$K$346,0)),"") | D31: =IFERROR(INDEX(Armour!$H$2:$H$346,MATCH(D$13&"#"&18,Armour!$K$2:$K$346,0)),"") | E31: =IFERROR(INDEX(Armour!$H$2:$H$346,MATCH(E$13&"#"&18,Armour!$K$2:$K$346,0)),"")
A32: =IFERROR(INDEX(Armour!$H$2:$H$346,MATCH(A$13&"#"&19,Armour!$K$2:$K$346,0)),"") | B32: =IFERROR(INDEX(Armour!$H$2:$H$346,MATCH(B$13&"#"&19,Armour!$K$2:$K$346,0)),"") | C32: =IFERROR(INDEX(Armour!$H$2:$H$346,MATCH(C$13&"#"&19,Armour!$K$2:$K$346,0)),"") | D32: =IFERROR(INDEX(Armour!$H$2:$H$346,MATCH(D$13&"#"&19,Armour!$K$2:$K$346,0)),"") | E32: =IFERROR(INDEX(Armour!$H$2:$H$346,MATCH(E$13&"#"&19,Armour!$K$2:$K$346,0)),"")
A33: =IFERROR(INDEX(Armour!$H$2:$H$346,MATCH(A$13&"#"&20,Armour!$K$2:$K$346,0)),"") | B33: =IFERROR(INDEX(Armour!$H$2:$H$346,MATCH(B$13&"#"&20,Armour!$K$2:$K$346,0)),"") | C33: =IFERROR(INDEX(Armour!$H$2:$H$346,MATCH(C$13&"#"&20,Armour!$K$2:$K$346,0)),"") | D33: =IFERROR(INDEX(Armour!$H$2:$H$346,MATCH(D$13&"#"&20,Armour!$K$2:$K$346,0)),"") | E33: =IFERROR(INDEX(Armour!$H$2:$H$346,MATCH(E$13&"#"&20,Armour!$K$2:$K$346,0)),"")
A34: ="— "&COUNTIFS(Armour!$B$2:$B$346,A$13,Armour!$I$2:$I$346,">0")&" match; showing up to 20" | B34: ="— "&COUNTIFS(Armour!$B$2:$B$346,B$13,Armour!$I$2:$I$346,">0")&" match; showing up to 20" | C34: ="— "&COUNTIFS(Armour!$B$2:$B$346,C$13,Armour!$I$2:$I$346,">0")&" match; showing up to 20" | D34: ="— "&COUNTIFS(Armour!$B$2:$B$346,D$13,Armour!$I$2:$I$346,">0")&" match; showing up to 20" | E34: ="— "&COUNTIFS(Armour!$B$2:$B$346,E$13,Armour!$I$2:$I$346,">0")&" match; showing up to 20"
A36: 3. Your build — pick one piece per slot
A37: Slot | B37: Piece | C37: Defence | D37: Drift slots
A38: Head | C38: =IF($B38="","",IFERROR(INDEX(Armour!$D$2:$D$346,MATCH($B38,Armour!$A$2:$A$346,0)),"")) | D38: =IF($B38="","",IFERROR(INDEX(Armour!$E$2:$E$346,MATCH($B38,Armour!$A$2:$A$346,0)),""))
A39: Chest | C39: =IF($B39="","",IFERROR(INDEX(Armour!$D$2:$D$346,MATCH($B39,Armour!$A$2:$A$346,0)),"")) | D39: =IF($B39="","",IFERROR(INDEX(Armour!$E$2:$E$346,MATCH($B39,Armour!$A$2:$A$346,0)),""))
A40: Arms | C40: =IF($B40="","",IFERROR(INDEX(Armour!$D$2:$D$346,MATCH($B40,Armour!$A$2:$A$346,0)),"")) | D40: =IF($B40="","",IFERROR(INDEX(Armour!$E$2:$E$346,MATCH($B40,Armour!$A$2:$A$346,0)),""))
A41: Waist | C41: =IF($B41="","",IFERROR(INDEX(Armour!$D$2:$D$346,MATCH($B41,Armour!$A$2:$A$346,0)),"")) | D41: =IF($B41="","",IFERROR(INDEX(Armour!$E$2:$E$346,MATCH($B41,Armour!$A$2:$A$346,0)),""))
A42: Legs | C42: =IF($B42="","",IFERROR(INDEX(Armour!$D$2:$D$346,MATCH($B42,Armour!$A$2:$A$346,0)),"")) | D42: =IF($B42="","",IFERROR(INDEX(Armour!$E$2:$E$346,MATCH($B42,Armour!$A$2:$A$346,0)),""))
...

Sheet About
A1: Monster Hunter Now — Armour Picker
A3: How to use it
A4: 1. On the Picker tab, choose up to 5 skills in the shaded cells (section 1).
A5: 2. Section 2 lists the armour in each slot carrying at least one of those skills,
A6: best matches first, shown as "Name — Skill (level), Skill (level)".
A7: 3. In section 3, pick one piece per slot from the shaded dropdowns.
A8: 4. Section 4 adds up the skills across the five pieces you picked.
A10: Clearing your choices
A11: To clear ONE skill, pick "(none)" — it is the first entry in the same dropdown.
A12: A dropdown built from a list offers no blank entry, which is why the sentinel exists.
A13: To drop them ALL at once, set "Ignore all wanted skills" to Yes. That leaves what you
A14: chose in place but stops it filtering, so every piece is listed again. Set it back to No
... A39: and working columns. You can ignore them.

Sheet Skills
A1: Skill | B1: Category | C1: Max level
A2: Advanced Attack Boost | B2: Attack | C2: 2
A3: Advanced Burst | B3: Attack | C3: 2
A4: Advanced Dragon Attack | B4: Element | C4: 2
A5: Advanced Ice Attack | B5: Element | C5: 2
A6: Advanced Thunder Attack | B6: Element | C6: 2
A7: Advanced Water Attack | B7: Element | C7: 2
A8: Aggressive Dodger | B8: Attack | C8: 5
A9: Ailment Opportunist | B9: Element | C9: 5
A10: Artful Dodger | B10: Action | C10: 3
A11: Artillery | B11: Attack | C11: 5
A12: Attack Boost | B12: Attack | C12: 5
A13: Attack Efficacy | B13: Attack | C13: 3
... A132: Windproof | B132: Defense/Resistance | C132: 3

Sheet Armour
A1: Name | B1: Slot | C1: Series | D1: Defence | E1: Drift slots | F1: Grade | G1: Skills | H1: Display | I1: Matches | J1: Rank | K1: Key | L1: Skill 1 | M1: Lv 1 | N1: Skill 2 | O1: Lv 2 | P1: Skill 3 | Q1: Lv 3
A2: Aknosom Helm | B2: Head | C2: Aknosom Set | D2: 197 | E2: 1 | F2: 10 | G2: Defensive Loading (2) | H2: Aknosom Helm — Defensive Loading (2) | I2: =IF(OR(Picker!$B$10="Yes",SUMPRODUCT((Picker!$A$5:$A$9<>"")*(Picker!$A$5:$A$9<>"(none)"))=0),1,IF($L2="",0,COUNTIF(Picker!$A$5:$A$9,$L2))+IF($N2="",0,COUNTIF(Picker!$A$5:$A$9,$N2))+IF($P2="",0,COUNTIF(Picker!$A$5:$A$9,$P2))) | J2: =IF($I2=0,"",COUNTIFS($B$2:$B$346,$B2,$I$2:$I$346,">"&$I2)+COUNTIFS($B$2:$B2,$B2,$I$2:$I2,$I2)) | K2: =IF($J2="","",$B2&"#"&$J2) | L2: Defensive Loading | M2: 2
A3: Alloy Helm | B3: Head | C3: Alloy Set | D3: 197 | E3: 1 | F3: 10 | G3: Earplugs (3) | H3: Alloy Helm — Earplugs (3) | I3: =IF(OR(Picker!$B$10="Yes",SUMPRODUCT((Picker!$A$5:$A$9<>"")*(Picker!$A$5:$A$9<>"(none)"))=0),1,IF($L3="",0,COUNTIF(Picker!$A$5:$A$9,$L3))+IF($N3="",0,COUNTIF(Picker!$A$5:$A$9,$N3))+IF($P3="",0,COUNTIF(Picker!$A$5:$A$9,$P3))) | J3: =IF($I3=0,"",COUNTIFS($B$2:$B$346,$B3,$I$2:$I$346,">"&$I3)+COUNTIFS($B$2:$B3,$B3,$I$2:$I3,$I3)) | K3: =IF($J3="","",$B3&"#"&$J3) | L3: Earplugs | M3: 3
A4: Almudron Helm | B4: Head | C4: Almudron Set | D4: 197 | E4: 1 | F4: 10 | G4: Water Attack (1), Sneak Attack (1), Advanced Water Attack (1) | H4: Almudron Helm — Water Attack (1), Sneak Attack (1), Advanced Water Attack (1) | I4: =IF(OR(Picker!$B$10="Yes",SUMPRODUCT((Picker!$A$5:$A$9<>"")*(Picker!$A$5:$A$9<>"(none)"))=0),1,IF($L4="",0,COUNTIF(Picker!$A$5:$A$9,$L4))+IF($N4="",0,COUNTIF(Picker!$A$5:$A$9,$N4))+IF($P4="",0,COUNTIF(Picker!$A$5:$A$9,$P4))) | J4: =IF($I4=0,"",COUNTIFS($B$2:$B$346,$B4,$I$2:$I$346,">"&$I4)+COUNTIFS($B$2:$B4,$B4,$I$2:$I4,$I4)) | K4: =IF($J4="","",$B4&"#"&$J4) | L4: Water Attack | M4: 1 | N4: Sneak Attack | O4: 1 | P4: Advanced Water Attack | Q4: 1
A5: Anja Helm | B5: Head | C5: Anjanath Set | D5: 197 | E5: 1 | F5: 10 | G5: Fire Resistance (1), Fire Attack (2) | H5: Anja Helm — Fire Resistance (1), Fire Attack (2) | I5: =IF(OR(Picker!$B$10="Yes",SUMPRODUCT((Picker!$A$5:$A$9<>"")*(Picker!$A$5:$A$9<>"(none)"))=0),1,IF($L5="",0,COUNTIF(Picker!$A$5:$A$9,$L5))+IF($N5="",0,COUNTIF(Picker!$A$5:$A$9,$N5))+IF($P5="",0,COUNTIF(Picker!$A$5:$A$9,$P5))) | J5: =IF($I5=0,"",COUNTIFS($B$2:$B$346,$B5,$I$2:$I$346,">"&$I5)+COUNTIFS($B$2:$B5,$B5,$I$2:$I5,$I5)) | K5: =IF($J5="","",$B5&"#"&$J5) | L5: Fire Resistance | M5: 1 | N5: Fire Attack | O5: 2
A6: Arzuros Helm | B6: Head | C6: Arzuros Set | D6: 197 | E6: 1 | F6: 10 | G6: Shared Shield (1), Shared Sword (1) | H6: Arzuros Helm — Shared Shield (1), Shared Sword (1) | I6: =IF(OR(Picker!$B$10="Yes",SUMPRODUCT((Picker!$A$5:$A$9<>"")*(Picker!$A$5:$A$9<>"(none)"))=0),1,IF($L6="",0,COUNTIF(Picker!$A$5:$A$9,$L6))+IF($N6="",0,COUNTIF(Picker!$A$5:$A$9,$N6))+IF($P6="",0,COUNTIF(Picker!$A$5:$A$9,$P6))) | J6: =IF($I6=0,"",COUNTIFS($B$2:$B$346,$B6,$I$2:$I$346,">"&$I6)+COUNTIFS($B$2:$B6,$B6,$I$2:$I6,$I6)) | K6: =IF($J6="","",$B6&"#"&$J6) | L6: Shared Shield | M6: 1 | N6: Shared Sword | O6: 1
A7: Astalos Helm | B7: Head | C7: Astalos Set | D7: 197 | E7: 1 | F7: 10 | G7: Thunder Attack (1), Reload Speed (1), Advanced Thunder Attack (1) | H7: Astalos Helm — Thunder Attack (1), Reload Speed (1), Advanced Thunder Attack (1) | I7: =IF(OR(Picker!$B$10="Yes",SUMPRODUCT((Picker!$A$5:$A$9<>"")*(Picker!$A$5:$A$9<>"(none)"))=0),1,IF($L7="",0,COUNTIF(Picker!$A$5:$A$9,$L7))+IF($N7="",0,COUNTIF(Picker!$A$5:$A$9,$N7))+IF($P7="",0,COUNTIF(Picker!$A$5:$A$9,$P7))) | J7: =IF($I7=0,"",COUNTIFS($B$2:$B$346,$B7,$I$2:$I$346,">"&$I7)+COUNTIFS($B$2:$B7,$B7,$I$2:$I7,$I7)) | K7: =IF($J7="","",$B7&"#"&$J7) | L7: Thunder Attack | M7: 1 | N7: Reload Speed | O7: 1 | P7: Advanced Thunder Attack | Q7: 1
A8: Baan Helm | B8: Head | C8: Radobaan Set | D8: 197 | E8: 1 | F8: 10 | G8: Guard (2) | H8: Baan Helm — Guard (2) | I8: =IF(OR(Picker!$B$10="Yes",SUMPRODUCT((Picker!$A$5:$A$9<>"")*(Picker!$A$5:$A$9<>"(none)"))=0),1,IF($L8="",0,COUNTIF(Picker!$A$5:$A$9,$L8))+IF($N8="",0,COUNTIF(Picker!$A$5:$A$9,$N8))+IF($P8="",0,COUNTIF(Picker!$A$5:$A$9,$P8))) | J8: =IF($I8=0,"",COUNTIFS($B$2:$B$346,$B8,$I$2:$I$346,">"&$I8)+COUNTIFS($B$2:$B8,$B8,$I$2:$I8,$I8)) | K8: =IF($J8="","",$B8&"#"&$J8) | L8: Guard | M8: 2
A9: Banbaro Helm | B9: Head | C9: Banbaro Set | D9: 197 | E9: 1 | F9: 10 | G9: Recoil Down (1), Tremor Resistance (1) | H9: Banbaro Helm — Recoil Down (1), Tremor Resistance (1) | I9: =IF(OR(Picker!$B$10="Yes",SUMPRODUCT((Picker!$A$5:$A$9<>"")*(Picker!$A$5:$A$9<>"(none)"))=0),1,IF($L9="",0,COUNTIF(Picker!$A$5:$A$9,$L9))+IF($N9="",0,COUNTIF(Picker!$A$5:$A$9,$N9))+IF($P9="",0,COUNTIF(Picker!$A$5:$A$9,$P9))) | J9: =IF($I9=0,"",COUNTIFS($B$2:$B$346,$B9,$I$2:$I$346,">"&$I9)+COUNTIFS($B$2:$B9,$B9,$I$2:$I9,$I9)) | K9: =IF($J9="","",$B9&"#"&$J9) | L9: Recoil Down | M9: 1 | N9: Tremor Resistance | O9: 1
A10: Barioth Helm | B10: Head | C10: Barioth Set | D10: 197 | E10: 1 | F10: 10 | G10: Evade Extender (1), Skyward Striker (2) | H10: Barioth Helm — Evade Extender (1), Skyward Striker (2) | I10: =IF(OR(Picker!$B$10="Yes",SUMPRODUCT((Picker!$A$5:$A$9<>"")*(Picker!$A$5:$A$9<>"(none)"))=0),1,IF($L10="",0,COUNTIF(Picker!$A$5:$A$9,$L10))+IF($N10="",0,COUNTIF(Picker!$A$5:$A$9,$N10))+IF($P10="",0,COUNTIF(Picker!$A$5:$A$9,$P10))) | J10: =IF($I10=0,"",COUNTIFS($B$2:$B$346,$B10,$I$2:$I$346,">"&$I10)+COUNTIFS($B$2:$B10,$B10,$I$2:$I10,$I10)) | K10: =IF($J10="","",$B10&"#"&$J10) | L10: Evade Extender | M10: 1 | N10: Skyward Striker | O10: 2
A11: Barroth Helm | B11: Head | C11: Barroth Set | D11: 197 | E11: 1 | F11: 10 | G11: Defense Boost (1), Offensive Guard (2) | H11: Barroth Helm — Defense Boost (1), Offensive Guard (2) | I11: =IF(OR(Picker!$B$10="Yes",SUMPRODUCT((Picker!$A$5:$A$9<>"")*(Picker!$A$5:$A$9<>"(none)"))=0),1,IF($L11="",0,COUNTIF(Picker!$A$5:$A$9,$L11))+IF($N11="",0,COUNTIF(Picker!$A$5:$A$9,$N11))+IF($P11="",0,COUNTIF(Picker!$A$5:$A$9,$P11))) | J11: =IF($I11=0,"",COUNTIFS($B$2:$B$346,$B11,$I$2:$I$346,">"&$I11)+COUNTIFS($B$2:$B11,$B11,$I$2:$I11,$I11)) | K11: =IF($J11="","",$B11&"#"&$J11) | L11: Defense Boost | M11: 1 | N11: Offensive Guard | O11: 2
A12: Basarios Helm | B12: Head | C12: Basarios Set | D12: 197 | E12: 2 | F12: 10 | G12: Sleep Resistance (2) | H12: Basarios Helm — Sleep Resistance (2) | I12: =IF(OR(Picker!$B$10="Yes",SUMPRODUCT((Picker!$A$5:$A$9<>"")*(Picker!$A$5:$A$9<>"(none)"))=0),1,IF($L12="",0,COUNTIF(Picker!$A$5:$A$9,$L12))+IF($N12="",0,COUNTIF(Picker!$A$5:$A$9,$N12))+IF($P12="",0,COUNTIF(Picker!$A$5:$A$9,$P12))) | J12: =IF($I12=0,"",COUNTIFS($B$2:$B$346,$B12,$I$2:$I$346,">"&$I12)+COUNTIFS($B$2:$B12,$B12,$I$2:$I12,$I12)) | K12: =IF($J12="","",$B12&"#"&$J12) | L12: Sleep Resistance | M12: 2
A13: Bazelgeuse Helm | B13: Head | C13: Bazelgeuse Set | D13: 197 | E13: 1 | F13: 10 | G13: Reload Speed (2), Artillery (1) | H13: Bazelgeuse Helm — Reload Speed (2), Artillery (1) | I13: =IF(OR(Picker!$B$10="Yes",SUMPRODUCT((Picker!$A$5:$A$9<>"")*(Picker!$A$5:$A$9<>"(none)"))=0),1,IF($L13="",0,COUNTIF(Picker!$A$5:$A$9,$L13))+IF($N13="",0,COUNTIF(Picker!$A$5:$A$9,$N13))+IF($P13="",0,COUNTIF(Picker!$A$5:$A$9,$P13))) | J13: =IF($I13=0,"",COUNTIFS($B$2:$B$346,$B13,$I$2:$I$346,">"&$I13)+COUNTIFS($B$2:$B13,$B13,$I$2:$I13,$I13)) | K13: =IF($J13="","",$B13&"#"&$J13) | L13: Reload Speed | M13: 2 | N13: Artillery | O13: 1
A14: Beotodus Helm | B14: Head | C14: Beotodus Set | D14: 197 | E14: 1 | F14: 10 | G14: Peak Performance (3) | H14: Beotodus Helm — Peak Performance (3) | I14: =IF(OR(Picker!$B$10="Yes",SUMPRODUCT((Picker!$A$5:$A$9<>"")*(Picker!$A$5:$A$9<>"(none)"))=0),1,IF($L14="",0,COUNTIF(Picker!$A$5:$A$9,$L14))+IF($N14="",0,COUNTIF(Picker!$A$5:$A$9,$N14))+IF($P14="",0,COUNTIF(Picker!$A$5:$A$9,$P14))) | J14: =IF($I14=0,"",COUNTIFS($B$2:$B$346,$B14,$I$2:$I$346,">"&$I14)+COUNTIFS($B$2:$B14,$B14,$I$2:$I14,$I14)) | K14: =IF($J14="","",$B14&"#"&$J14) | L14: Peak Performance | M14: 3
A15: Bishaten Helm | B15: Head | C15: Bishaten Set | D15: 197 | E15: 1 | F15: 10 | G15: Paralysis Exploit (2) | H15: Bishaten Helm — Paralysis Exploit (2) | I15: =IF(OR(Picker!$B$10="Yes",SUMPRODUCT((Picker!$A$5:$A$9<>"")*(Picker!$A$5:$A$9<>"(none)"))=0),1,IF($L15="",0,COUNTIF(Picker!$A$5:$A$9,$L15))+IF($N15="",0,COUNTIF(Picker!$A$5:$A$9,$N15))+IF($P15="",0,COUNTIF(Picker!$A$5:$A$9,$P15))) | J15: =IF($I15=0,"",COUNTIFS($B$2:$B$346,$B15,$I$2:$I$346,">"&$I15)+COUNTIFS($B$2:$B15,$B15,$I$2:$I15,$I15)) | K15: =IF($J15="","",$B15&"#"&$J15) | L15: Paralysis Exploit | M15: 2
A16: Ceanataur Helm | B16: Head | C16: Ceanataur Set | D16: 197 | E16: 1 | F16: 10 | G16: Pursuit (1), Vital Water (1) | H16: Ceanataur Helm — Pursuit (1), Vital Water (1) | I16: =IF(OR(Picker!$B$10="Yes",SUMPRODUCT((Picker!$A$5:$A$9<>"")*(Picker!$A$5:$A$9<>"(none)"))=0),1,IF($L16="",0,COUNTIF(Picker!$A$5:$A$9,$L16))+IF($N16="",0,COUNTIF(Picker!$A$5:$A$9,$N16))+IF($P16="",0,COUNTIF(Picker!$A$5:$A$9,$P16))) | J16: =IF($I16=0,"",COUNTIFS($B$2:$B$346,$B16,$I$2:$I$346,">"&$I16)+COUNTIFS($B$2:$B16,$B16,$I$2:$I16,$I16)) | K16: =IF($J16="","",$B16&"#"&$J16) | L16: Pursuit | M16: 1 | N16: Vital Water | O16: 1
A17: Chatacabra Helm | B17: Head | C17: Chatacabra Set | D17: 197 | E17: 1 | F17: 10 | G17: Sneak Attack (2), Litheness (1) | H17: Chatacabra Helm — Sneak Attack (2), Litheness (1) | I17: =IF(OR(Picker!$B$10="Yes",SUMPRODUCT((Picker!$A$5:$A$9<>"")*(Picker!$A$5:$A$9<>"(none)"))=0),1,IF($L17="",0,COUNTIF(Picker!$A$5:$A$9,$L17))+IF($N17="",0,COUNTIF(Picker!$A$5:$A$9,$N17))+IF($P17="",0,COUNTIF(Picker!$A$5:$A$9,$P17))) | J17: =IF($I17=0,"",COUNTIFS($B$2:$B$346,$B17,$I$2:$I$346,">"&$I17)+COUNTIFS($B$2:$B17,$B17,$I$2:$I17,$I17)) | K17: =IF($J17="","",$B17&"#"&$J17) | L17: Sneak Attack | M17: 2 | N17: Litheness | O17: 1
A18: Death Garon Helm | B18: Head | C18: Death Garon Set | D18: 197 | E18: 1 | F18: 10 | G18: Resuscitate (1), Bleeding Edge (1) | H18: Death Garon Helm — Resuscitate (1), Bleeding Edge (1) | I18: =IF(OR(Picker!$B$10="Yes",SUMPRODUCT((Picker!$A$5:$A$9<>"")*(Picker!$A$5:$A$9<>"(none)"))=0),1,IF($L18="",0,COUNTIF(Picker!$A$5:$A$9,$L18))+IF($N18="",0,COUNTIF(Picker!$A$5:$A$9,$N18))+IF($P18="",0,COUNTIF(Picker!$A$5:$A$9,$P18))) | J18: =IF($I18=0,"",COUNTIFS($B$2:$B$346,$B18,$I$2:$I$346,">"&$I18)+COUNTIFS($B$2:$B18,$B18,$I$2:$I18,$I18)) | K18: =IF($J18="","",$B18&"#"&$J18) | L18: Resuscitate | M18: 1 | N18: Bleeding Edge | O18: 1
A19: Diablos Helm | B19: Head | C19: Diablos Set | D19: 197 | E19: 1 | F19: 10 | G19: Heroics (2) | H19: Diablos Helm — Heroics (2) | I19: =IF(OR(Picker!$B$10="Yes",SUMPRODUCT((Picker!$A$5:$A$9<>"")*(Picker!$A$5:$A$9<>"(none)"))=0),1,IF($L19="",0,COUNTIF(Picker!$A$5:$A$9,$L19))+IF($N19="",0,COUNTIF(Picker!$A$5:$A$9,$N19))+IF($P19="",0,COUNTIF(Picker!$A$5:$A$9,$P19))) | J19: =IF($I19=0,"",COUNTIFS($B$2:$B$346,$B19,$I$2:$I$346,">"&$I19)+COUNTIFS($B$2:$B19,$B19,$I$2:$I19,$I19)) | K19: =IF($J19="","",$B19&"#"&$J19) | L19: Heroics | M19: 2
A20: Diablos Nero Helm | B20: Head | C20: Black Diablos Set | D20: 197 | E20: 1 | F20: 10 | G20: Partbreaker (2), Resentment (1) | H20: Diablos Nero Helm — Partbreaker (2), Resentment (1) | I20: =IF(OR(Picker!$B$10="Yes",SUMPRODUCT((Picker!$A$5:$A$9<>"")*(Picker!$A$5:$A$9<>"(none)"))=0),1,IF($L20="",0,COUNTIF(Picker!$A$5:$A$9,$L20))+IF($N20="",0,COUNTIF(Picker!$A$5:$A$9,$N20))+IF($P20="",0,COUNTIF(Picker!$A$5:$A$9,$P20))) | J20: =IF($I20=0,"",COUNTIFS($B$2:$B$346,$B20,$I$2:$I$346,">"&$I20)+COUNTIFS($B$2:$B20,$B20,$I$2:$I20,$I20)) | K20: =IF($J20="","",$B20&"#"&$J20) | L20: Partbreaker | M20: 2 | N20: Resentment | O20: 1
A21: Espinas Brain | B21: Head | C21: Espinas Set | D21: 197 | E21: 1 | F21: 10 | G21: Health Boost (1), Vital Fire (1) | H21: Espinas Brain — Health Boost (1), Vital Fire (1) | I21: =IF(OR(Picker!$B$10="Yes",SUMPRODUCT((Picker!$A$5:$A$9<>"")*(Picker!$A$5:$A$9<>"(none)"))=0),1,IF($L21="",0,COUNTIF(Picker!$A$5:$A$9,$L21))+IF($N21="",0,COUNTIF(Picker!$A$5:$A$9,$N21))+IF($P21="",0,COUNTIF(Picker!$A$5:$A$9,$P21))) | J21: =IF($I21=0,"",COUNTIFS($B$2:$B$346,$B21,$I$2:$I$346,">"&$I21)+COUNTIFS($B$2:$B21,$B21,$I$2:$I21,$I21)) | K21: =IF($J21="","",$B21&"#"&$J21) | L21: Health Boost | M21: 1 | N21: Vital Fire | O21: 1
A22: Fulgur Helm | B22: Head | C22: Fulgur Set | D22: 197 | E22: 1 | F22: 10 | G22: Special Boost (1), Special Partbreaker (2) | H22: Fulgur Helm — Special Boost (1), Special Partbreaker (2) | I22: =IF(OR(Picker!$B$10="Yes",SUMPRODUCT((Picker!$A$5:$A$9<>"")*(Picker!$A$5:$A$9<>"(none)"))=0),1,IF($L22="",0,COUNTIF(Picker!$A$5:$A$9,$L22))+IF($N22="",0,COUNTIF(Picker!$A$5:$A$9,$N22))+IF($P22="",0,COUNTIF(Picker!$A$5:$A$9,$P22))) | J22: =IF($I22=0,"",COUNTIFS($B$2:$B$346,$B22,$I$2:$I$346,">"&$I22)+COUNTIFS($B$2:$B22,$B22,$I$2:$I22,$I22)) | K22: =IF($J22="","",$B22&"#"&$J22) | L22: Special Boost | M22: 1 | N22: Special Partbreaker | O22: 2
A23: Girros Mask | B23: Head | C23: Girros Set | D23: 197 | E23: 2 | F23: 10 | G23: Paralysis Resistance (3) | H23: Girros Mask — Paralysis Resistance (3) | I23: =IF(OR(Picker!$B$10="Yes",SUMPRODUCT((Picker!$A$5:$A$9<>"")*(Picker!$A$5:$A$9<>"(none)"))=0),1,IF($L23="",0,COUNTIF(Picker!$A$5:$A$9,$L23))+IF($N23="",0,COUNTIF(Picker!$A$5:$A$9,$N23))+IF($P23="",0,COUNTIF(Picker!$A$5:$A$9,$P23))) | J23: =IF($I23=0,"",COUNTIFS($B$2:$B$346,$B23,$I$2:$I$346,">"&$I23)+COUNTIFS($B$2:$B23,$B23,$I$2:$I23,$I23)) | K23: =IF($J23="","",$B23&"#"&$J23) | L23: Paralysis Resistance | M23: 3
A24: Glavenus Helm | B24: Head | C24: Glavenus Set | D24: 197 | E24: 1 | F24: 10 | G24: Raw Power (2) | H24: Glavenus Helm — Raw Power (2) | I24: =IF(OR(Picker!$B$10="Yes",SUMPRODUCT((Picker!$A$5:$A$9<>"")*(Picker!$A$5:$A$9<>"(none)"))=0),1,IF($L24="",0,COUNTIF(Picker!$A$5:$A$9,$L24))+IF($N24="",0,COUNTIF(Picker!$A$5:$A$9,$N24))+IF($P24="",0,COUNTIF(Picker!$A$5:$A$9,$P24))) | J24: =IF($I24=0,"",COUNTIFS($B$2:$B$346,$B24,$I$2:$I$346,">"&$I24)+COUNTIFS($B$2:$B24,$B24,$I$2:$I24,$I24)) | K24: =IF($J24="","",$B24&"#"&$J24) | L24: Raw Power | M24: 2
A25: Golden Headdress | B25: Head | C25: Golden Set | D25: 197 | E25: 2 | F25: 10 | G25: Thunder Resistance (3) | H25: Golden Headdress — Thunder Resistance (3) | I25: =IF(OR(Picker!$B$10="Yes",SUMPRODUCT((Picker!$A$5:$A$9<>"")*(Picker!$A$5:$A$9<>"(none)"))=0),1,IF($L25="",0,COUNTIF(Picker!$A$5:$A$9,$L25))+IF($N25="",0,COUNTIF(Picker!$A$5:$A$9,$N25))+IF($P25="",0,COUNTIF(Picker!$A$5:$A$9,$P25))) | J25: =IF($I25=0,"",COUNTIFS($B$2:$B$346,$B25,$I$2:$I$346,">"&$I25)+COUNTIFS($B$2:$B25,$B25,$I$2:$I25,$I25)) | K25: =IF($J25="","",$B25&"#"&$J25) | L25: Thunder Resistance | M25: 3
A26: Golden Lunehelm | B26: Head | C26: Golden Lune Set | D26: 197 | E26: 1 | F26: 10 | G26: Divine Blessing (2), Resentment (1) | H26: Golden Lunehelm — Divine Blessing (2), Resentment (1) | I26: =IF(OR(Picker!$B$10="Yes",SUMPRODUCT((Picker!$A$5:$A$9<>"")*(Picker!$A$5:$A$9<>"(none)"))=0),1,IF($L26="",0,COUNTIF(Picker!$A$5:$A$9,$L26))+IF($N26="",0,COUNTIF(Picker!$A$5:$A$9,$N26))+IF($P26="",0,COUNTIF(Picker!$A$5:$A$9,$P26))) | J26: =IF($I26=0,"",COUNTIFS($B$2:$B$346,$B26,$I$2:$I$346,">"&$I26)+COUNTIFS($B$2:$B26,$B26,$I$2:$I26,$I26)) | K26: =IF($J26="","",$B26&"#"&$J26) | L26: Divine Blessing | M26: 2 | N26: Resentment | O26: 1
A27: Golm Helm | B27: Head | C27: Garangolm Set | D27: 197 | E27: 1 | F27: 10 | G27: Critical Ferocity (2) | H27: Golm Helm — Critical Ferocity (2) | I27: =IF(OR(Picker!$B$10="Yes",SUMPRODUCT((Picker!$A$5:$A$9<>"")*(Picker!$A$5:$A$9<>"(none)"))=0),1,IF($L27="",0,COUNTIF(Picker!$A$5:$A$9,$L27))+IF($N27="",0,COUNTIF(Picker!$A$5:$A$9,$N27))+IF($P27="",0,COUNTIF(Picker!$A$5:$A$9,$P27))) | J27: =IF($I27=0,"",COUNTIFS($B$2:$B$346,$B27,$I$2:$I$346,">"&$I27)+COUNTIFS($B$2:$B27,$B27,$I$2:$I27,$I27)) | K27: =IF($J27="","",$B27&"#"&$J27) | L27: Critical Ferocity | M27: 2
A28: Goss Harag Helm | B28: Head | C28: Goss Harag Set | D28: 197 | E28: 1 | F28: 10 | G28: Morph Boost (1), Morph Attack Boost (1) | H28: Goss Harag Helm — Morph Boost (1), Morph Attack Boost (1) | I28: =IF(OR(Picker!$B$10="Yes",SUMPRODUCT((Picker!$A$5:$A$9<>"")*(Picker!$A$5:$A$9<>"(none)"))=0),1,IF($L28="",0,COUNTIF(Picker!$A$5:$A$9,$L28))+IF($N28="",0,COUNTIF(Picker!$A$5:$A$9,$N28))+IF($P28="",0,COUNTIF(Picker!$A$5:$A$9,$P28))) | J28: =IF($I28=0,"",COUNTIFS($B$2:$B$346,$B28,$I$2:$I$346,">"&$I28)+COUNTIFS($B$2:$B28,$B28,$I$2:$I28,$I28)) | K28: =IF($J28="","",$B28&"#"&$J28) | L28: Morph Boost | M28: 1 | N28: Morph Attack Boost | O28: 1
A29: Jagras Helm | B29: Head | C29: Jagras Set | D29: 197 | E29: 2 | F29: 10 | G29: Firm Foothold (2) | H29: Jagras Helm — Firm Foothold (2) | I29: =IF(OR(Picker!$B$10="Yes",SUMPRODUCT((Picker!$A$5:$A$9<>"")*(Picker!$A$5:$A$9<>"(none)"))=0),1,IF($L29="",0,COUNTIF(Picker!$A$5:$A$9,$L29))+IF($N29="",0,COUNTIF(Picker!$A$5:$A$9,$N29))+IF($P29="",0,COUNTIF(Picker!$A$5:$A$9,$P29))) | J29: =IF($I29=0,"",COUNTIFS($B$2:$B$346,$B29,$I$2:$I$346,">"&$I29)+COUNTIFS($B$2:$B29,$B29,$I$2:$I29,$I29)) | K29: =IF($J29="","",$B29&"#"&$J29) | L29: Firm Foothold | M29: 2
A30: Jyura Helm | B30: Head | C30: Jyuratodus Set | D30: 197 | E30: 2 | F30: 10 | G30: Water Resistance (1), Last Stand (1) | H30: Jyura Helm — Water Resistance (1), Last Stand (1) | I30: =IF(OR(Picker!$B$10="Yes",SUMPRODUCT((Picker!$A$5:$A$9<>"")*(Picker!$A$5:$A$9<>"(none)"))=0),1,IF($L30="",0,COUNTIF(Picker!$A$5:$A$9,$L30))+IF($N30="",0,COUNTIF(Picker!$A$5:$A$9,$N30))+IF($P30="",0,COUNTIF(Picker!$A$5:$A$9,$P30))) | J30: =IF($I30=0,"",COUNTIFS($B$2:$B$346,$B30,$I$2:$I$346,">"&$I30)+COUNTIFS($B$2:$B30,$B30,$I$2:$I30,$I30)) | K30: =IF($J30="","",$B30&"#"&$J30) | L30: Water Resistance | M30: 1 | N30: Last Stand | O30: 1
A31: Kadachi Helm | B31: Head | C31: Kadachi Set | D31: 197 | E31: 1 | F31: 10 | G31: Reload Speed (1), Artful Dodger (2) | H31: Kadachi Helm — Reload Speed (1), Artful Dodger (2) | I31: =IF(OR(Picker!$B$10="Yes",SUMPRODUCT((Picker!$A$5:$A$9<>"")*(Picker!$A$5:$A$9<>"(none)"))=0),1,IF($L31="",0,COUNTIF(Picker!$A$5:$A$9,$L31))+IF($N31="",0,COUNTIF(Picker!$A$5:$A$9,$N31))+IF($P31="",0,COUNTIF(Picker!$A$5:$A$9,$P31))) | J31: =IF($I31=0,"",COUNTIFS($B$2:$B$346,$B31,$I$2:$I$346,">"&$I31)+COUNTIFS($B$2:$B31,$B31,$I$2:$I31,$I31)) | K31: =IF($J31="","",$B31&"#"&$J31) | L31: Reload Speed | M31: 1 | N31: Artful Dodger | O31: 2
A32: Kaiser Crown | B32: Head | C32: Kaiser Set | D32: 197 | E32: 1 | F32: 10 | G32: Guts (1), Latent Power (2), Teostra Blastpowder (1) | H32: Kaiser Crown — Guts (1), Latent Power (2), Teostra Blastpowder (1) | I32: =IF(OR(Picker!$B$10="Yes",SUMPRODUCT((Picker!$A$5:$A$9<>"")*(Picker!$A$5:$A$9<>"(none)"))=0),1,IF($L32="",0,COUNTIF(Picker!$A$5:$A$9,$L32))+IF($N32="",0,COUNTIF(Picker!$A$5:$A$9,$N32))+IF($P32="",0,COUNTIF(Picker!$A$5:$A$9,$P32))) | J32: =IF($I32=0,"",COUNTIFS($B$2:$B$346,$B32,$I$2:$I$346,">"&$I32)+COUNTIFS($B$2:$B32,$B32,$I$2:$I32,$I32)) | K32: =IF($J32="","",$B32&"#"&$J32) | L32: Guts | M32: 1 | N32: Latent Power | O32: 2 | P32: Teostra Blastpowder | Q32: 1
A33: Khezu Helm | B33: Head | C33: Khezu Set | D33: 197 | E33: 1 | F33: 10 | G33: Paralysis Attack (1), Special Insurance (1) | H33: Khezu Helm — Paralysis Attack (1), Special Insurance (1) | I33: =IF(OR(Picker!$B$10="Yes",SUMPRODUCT((Picker!$A$5:$A$9<>"")*(Picker!$A$5:$A$9<>"(none)"))=0),1,IF($L33="",0,COUNTIF(Picker!$A$5:$A$9,$L33))+IF($N33="",0,COUNTIF(Picker!$A$5:$A$9,$N33))+IF($P33="",0,COUNTIF(Picker!$A$5:$A$9,$P33))) | J33: =IF($I33=0,"",COUNTIFS($B$2:$B$346,$B33,$I$2:$I$346,">"&$I33)+COUNTIFS($B$2:$B33,$B33,$I$2:$I33,$I33)) | K33: =IF($J33="","",$B33&"#"&$J33) | L33: Paralysis Attack | M33: 1 | N33: Special Insurance | O33: 1
A34: Kirin Horn | B34: Head | C34: Kirin Set | D34: 197 | E34: 1 | F34: 10 | G34: Lock On (1), Fighting Spirit (1), Kirin Flashstorm (1) | H34: Kirin Horn — Lock On (1), Fighting Spirit (1), Kirin Flashstorm (1) | I34: =IF(OR(Picker!$B$10="Yes",SUMPRODUCT((Picker!$A$5:$A$9<>"")*(Picker!$A$5:$A$9<>"(none)"))=0),1,IF($L34="",0,COUNTIF(Picker!$A$5:$A$9,$L34))+IF($N34="",0,COUNTIF(Picker!$A$5:$A$9,$N34))+IF($P34="",0,COUNTIF(Picker!$A$5:$A$9,$P34))) | J34: =IF($I34=0,"",COUNTIFS($B$2:$B$346,$B34,$I$2:$I$346,">"&$I34)+COUNTIFS($B$2:$B34,$B34,$I$2:$I34,$I34)) | K34: =IF($J34="","",$B34&"#"&$J34) | L34: Lock On | M34: 1 | N34: Fighting Spirit | O34: 1 | P34: Kirin Flashstorm | Q34: 1
A35: Kulu Headpiece | B35: Head | C35: Kulu Set | D35: 197 | E35: 1 | F35: 10 | G35: Critical Eye (1), Lock On (1) | H35: Kulu Headpiece — Critical Eye (1), Lock On (1) | I35: =IF(OR(Picker!$B$10="Yes",SUMPRODUCT((Picker!$A$5:$A$9<>"")*(Picker!$A$5:$A$9<>"(none)"))=0),1,IF($L35="",0,COUNTIF(Picker!$A$5:$A$9,$L35))+IF($N35="",0,COUNTIF(Picker!$A$5:$A$9,$N35))+IF($P35="",0,COUNTIF(Picker!$A$5:$A$9,$P35))) | J35: =IF($I35=0,"",COUNTIFS($B$2:$B$346,$B35,$I$2:$I$346,">"&$I35)+COUNTIFS($B$2:$B35,$B35,$I$2:$I35,$I35)) | K35: =IF($J35="","",$B35&"#"&$J35) | L35: Critical Eye | M35: 1 | N35: Lock On | O35: 1
A36: Kushala Glare | B36: Head | C36: Kushala Set | D36: 197 | E36: 1 | F36: 10 | G36: Earplugs (1), Reload Speed (2), Kushala Frostwind (1) | H36: Kushala Glare — Earplugs (1), Reload Speed (2), Kushala Frostwind (1) | I36: =IF(OR(Picker!$B$10="Yes",SUMPRODUCT((Picker!$A$5:$A$9<>"")*(Picker!$A$5:$A$9<>"(none)"))=0),1,IF($L36="",0,COUNTIF(Picker!$A$5:$A$9,$L36))+IF($N36="",0,COUNTIF(Picker!$A$5:$A$9,$N36))+IF($P36="",0,COUNTIF(Picker!$A$5:$A$9,$P36))) | J36: =IF($I36=0,"",COUNTIFS($B$2:$B$346,$B36,$I$2:$I$346,">"&$I36)+COUNTIFS($B$2:$B36,$B36,$I$2:$I36,$I36)) | K36: =IF($J36="","",$B36&"#"&$J36) | L36: Earplugs | M36: 1 | N36: Reload Speed | O36: 2 | P36: Kushala Frostwind | Q36: 1
A37: Lagombi Helm | B37: Head | C37: Lagombi Set | D37: 197 | E37: 1 | F37: 10 | G37: Evade Extender (1), Special Boost (2) | H37: Lagombi Helm — Evade Extender (1), Special Boost (2) | I37: =IF(OR(Picker!$B$10="Yes",SUMPRODUCT((Picker!$A$5:$A$9<>"")*(Picker!$A$5:$A$9<>"(none)"))=0),1,IF($L37="",0,COUNTIF(Picker!$A$5:$A$9,$L37))+IF($N37="",0,COUNTIF(Picker!$A$5:$A$9,$N37))+IF($P37="",0,COUNTIF(Picker!$A$5:$A$9,$P37))) | J37: =IF($I37=0,"",COUNTIFS($B$2:$B$346,$B37,$I$2:$I$346,">"&$I37)+COUNTIFS($B$2:$B37,$B37,$I$2:$I37,$I37)) | K37: =IF($J37="","",$B37&"#"&$J37) | L37: Evade Extender | M37: 1 | N37: Special Boost | O37: 2
A38: Leather Headgear | B38: Head | C38: Leather Set | D38: 197 | E38: 1 | F38: 10 | G38: Ice Resistance (1), Critical Eye (1) | H38: Leather Headgear — Ice Resistance (1), Critical Eye (1) | I38: =IF(OR(Picker!$B$10="Yes",SUMPRODUCT((Picker!$A$5:$A$9<>"")*(Picker!$A$5:$A$9<>"(none)"))=0),1,IF($L38="",0,COUNTIF(Picker!$A$5:$A$9,$L38))+IF($N38="",0,COUNTIF(Picker!$A$5:$A$9,$N38))+IF($P38="",0,COUNTIF(Picker!$A$5:$A$9,$P38))) | J38: =IF($I38=0,"",COUNTIFS($B$2:$B$346,$B38,$I$2:$I$346,">"&$I38)+COUNTIFS($B$2:$B38,$B38,$I$2:$I38,$I38)) | K38: =IF($J38="","",$B38&"#"&$J38) | L38: Ice Resistance | M38: 1 | N38: Critical Eye | O38: 1
A39: Legiana Helm | B39: Head | C39: Legiana Set | D39: 197 | E39: 1 | F39: 10 | G39: Ice Attack (1), Divine Blessing (2) | H39: Legiana Helm — Ice Attack (1), Divine Blessing (2) | I39: =IF(OR(Picker!$B$10="Yes",SUMPRODUCT((Picker!$A$5:$A$9<>"")*(Picker!$A$5:$A$9<>"(none)"))=0),1,IF($L39="",0,COUNTIF(Picker!$A$5:$A$9,$L39))+IF($N39="",0,COUNTIF(Picker!$A$5:$A$9,$N39))+IF($P39="",0,COUNTIF(Picker!$A$5:$A$9,$P39))) | J39: =IF($I39=0,"",COUNTIFS($B$2:$B$346,$B39,$I$2:$I$346,">"&$I39)+COUNTIFS($B$2:$B39,$B39,$I$2:$I39,$I39)) | K39: =IF($J39="","",$B39&"#"&$J39) | L39: Ice Attack | M39: 1 | N39: Divine Blessing | O39: 2
A40: Lumu Hat | B40: Head | C40: Paolumu Set | D40: 197 | E40: 1 | F40: 10 | G40: Concentration (2), Windproof (1) | H40: Lumu Hat — Concentration (2), Windproof (1) | I40: =IF(OR(Picker!$B$10="Yes",SUMPRODUCT((Picker!$A$5:$A$9<>"")*(Picker!$A$5:$A$9<>"(none)"))=0),1,IF($L40="",0,COUNTIF(Picker!$A$5:$A$9,$L40))+IF($N40="",0,COUNTIF(Picker!$A$5:$A$9,$N40))+IF($P40="",0,COUNTIF(Picker!$A$5:$A$9,$P40))) | J40: =IF($I40=0,"",COUNTIFS($B$2:$B$346,$B40,$I$2:$I$346,">"&$I40)+COUNTIFS($B$2:$B40,$B40,$I$2:$I40,$I40)) | K40: =IF($J40="","",$B40&"#"&$J40) | L40: Concentration | M40: 2 | N40: Windproof | O40: 1
...

Sheet ArmourSkills
A1: Armour | B1: Slot | C1: Skill | D1: Level
A2: Aknosom Helm | B2: Head | C2: Defensive Loading | D2: 2
A3: Alloy Helm | B3: Head | C3: Earplugs | D3: 3
A4: Almudron Helm | B4: Head | C4: Water Attack | D4: 1
A5: Almudron Helm | B5: Head | C5: Sneak Attack | D5: 1
A6: Almudron Helm | B6: Head | C6: Advanced Water Attack | D6: 1
A7: Anja Helm | B7: Head | C7: Fire Resistance | D7: 1
A8: Anja Helm | B8: Head | C8: Fire Attack | D8: 2
A9: Arzuros Helm | B9: Head | C9: Shared Shield | D9: 1
A10: Arzuros Helm | B10: Head | C10: Shared Sword | D10: 1
A11: Astalos Helm | B11: Head | C11: Thunder Attack | D11: 1
A12: Astalos Helm | B12: Head | C12: Reload Speed | D12: 1
A13: Astalos Helm | B13: Head | C13: Advanced Thunder Attack | D13: 1
... A630: Zinogre Greaves | B630: Legs | C630: Burst | D630: 1

Sheet Lists
A1: Head | B1: Chest | C1: Arms | D1: Waist | E1: Legs | F1: Skill choice
A2: Aknosom Helm | B2: Aknosom Mail | C2: Aknosom Braces | D2: Aknosom Coil | E2: Aknosom Greaves | F2: (none)
A3: Alloy Helm | B3: Alloy Mail | C3: Alloy Vambraces | D3: Alloy Coil | E3: Alloy Greaves | F3: Advanced Attack Boost
A4: Almudron Helm | B4: Almudron Mail | C4: Almudron Vambraces | D4: Almudron Coil | E4: Almudron Greaves | F4: Advanced Burst
A5: Anja Helm | B5: Anja Mail | C5: Anja Vambraces | D5: Anja Coil | E5: Anja Greaves | F5: Advanced Dragon Attack
A6: Arzuros Helm | B6: Arzuros Mail | C6: Arzuros Vambraces | D6: Arzuros Coil | E6: Arzuros Greaves | F6: Advanced Ice Attack
A7: Astalos Helm | B7: Astalos Mail | C7: Astalos Braces | D7: Astalos Coil | E7: Astalos Greaves | F7: Advanced Thunder Attack
A8: Baan Helm | B8: Baan Mail | C8: Baan Vambraces | D8: Baan Coil | E8: Baan Greaves | F8: Advanced Water Attack
A9: Banbaro Helm | B9: Banbaro Mail | C9: Banbaro Vambraces | D9: Banbaro Coil | E9: Banbaro Greaves | F9: Aggressive Dodger
A10: Barioth Helm | B10: Barioth Mail | C10: Barioth Vambraces | D10: Barioth Faulds | E10: Barioth Greaves | F10: Ailment Opportunist
A11: Barroth Helm | B11: Barroth Mail | C11: Barroth Vambraces | D11: Barroth Coil | E11: Barroth Greaves | F11: Artful Dodger
A12: Basarios Helm | B12: Basarios Mail | C12: Basarios Vambraces | D12: Basarios Coil | E12: Basarios Greaves | F12: Artillery
... A70: Zinogre Helm | B70: Zinogre Mail | C70: Zinogre Braces | D70: Zinogre Coil | E70: Zinogre Greaves | F70: Lock On
F71: Malzeno Crimsonblood
F72: Meditation
F73: Morph Attack Boost
F74: Morph Boost
F75: Namielle Electrowave
F76: Nergigante Avidity
F77: Normal/Element Ammo Boost
F78: Offensive Dodger
F79: Offensive Guard
F80: Paralysis Attack
F81: Paralysis Exploit
F82: Paralysis Resistance
... F133: Windproof

Sheet Calc
A1: Skill | B1: Total in build | C1: Rank
A2: Advanced Attack Boost | B2: =SUMIFS(ArmourSkills!$D$2:$D$630,ArmourSkills!$A$2:$A$630,Picker!$B$38,ArmourSkills!$C$2:$C$630,$A2)+SUMIFS(ArmourSkills!$D$2:$D$630,ArmourSkills!$A$2:$A$630,Picker!$B$39,ArmourSkills!$C$2:$C$630,$A2)+SUMIFS(ArmourSkills!$D$2:$D$630,ArmourSkills!$A$2:$A$630,Picker!$B$40,ArmourSkills!$C$2:$C$630,$A2)+SUMIFS(ArmourSkills!$D$2:$D$630,ArmourSkills!$A$2:$A$630,Picker!$B$41,ArmourSkills!$C$2:$C$630,$A2)+SUMIFS(ArmourSkills!$D$2:$D$630,ArmourSkills!$A$2:$A$630,Picker!$B$42,ArmourSkills!$C$2:$C$630,$A2) | C2: =IF($B2=0,"",COUNTIF($B$2:$B$132,">"&$B2)+COUNTIF($B$2:$B2,$B2))
A3: Advanced Burst | B3: =SUMIFS(ArmourSkills!$D$2:$D$630,ArmourSkills!$A$2:$A$630,Picker!$B$38,ArmourSkills!$C$2:$C$630,$A3)+SUMIFS(ArmourSkills!$D$2:$D$630,ArmourSkills!$A$2:$A$630,Picker!$B$39,ArmourSkills!$C$2:$C$630,$A3)+SUMIFS(ArmourSkills!$D$2:$D$630,ArmourSkills!$A$2:$A$630,Picker!$B$40,ArmourSkills!$C$2:$C$630,$A3)+SUMIFS(ArmourSkills!$D$2:$D$630,ArmourSkills!$A$2:$A$630,Picker!$B$41,ArmourSkills!$C$2:$C$630,$A3)+SUMIFS(ArmourSkills!$D$2:$D$630,ArmourSkills!$A$2:$A$630,Picker!$B$42,ArmourSkills!$C$2:$C$630,$A3) | C3: =IF($B3=0,"",COUNTIF($B$2:$B$132,">"&$B3)+COUNTIF($B$2:$B3,$B3))
A4: Advanced Dragon Attack | B4: =SUMIFS(ArmourSkills!$D$2:$D$630,ArmourSkills!$A$2:$A$630,Picker!$B$38,ArmourSkills!$C$2:$C$630,$A4)+SUMIFS(ArmourSkills!$D$2:$D$630,ArmourSkills!$A$2:$A$630,Picker!$B$39,ArmourSkills!$C$2:$C$630,$A4)+SUMIFS(ArmourSkills!$D$2:$D$630,ArmourSkills!$A$2:$A$630,Picker!$B$40,ArmourSkills!$C$2:$C$630,$A4)+SUMIFS(ArmourSkills!$D$2:$D$630,ArmourSkills!$A$2:$A$630,Picker!$B$41,ArmourSkills!$C$2:$C$630,$A4)+SUMIFS(ArmourSkills!$D$2:$D$630,ArmourSkills!$A$2:$A$630,Picker!$B$42,ArmourSkills!$C$2:$C$630,$A4) | C4: =IF($B4=0,"",COUNTIF($B$2:$B$132,">"&$B4)+COUNTIF($B$2:$B4,$B4))
A5: Advanced Ice Attack | B5: =SUMIFS(ArmourSkills!$D$2:$D$630,ArmourSkills!$A$2:$A$630,Picker!$B$38,ArmourSkills!$C$2:$C$630,$A5)+SUMIFS(ArmourSkills!$D$2:$D$630,ArmourSkills!$A$2:$A$630,Picker!$B$39,ArmourSkills!$C$2:$C$630,$A5)+SUMIFS(ArmourSkills!$D$2:$D$630,ArmourSkills!$A$2:$A$630,Picker!$B$40,ArmourSkills!$C$2:$C$630,$A5)+SUMIFS(ArmourSkills!$D$2:$D$630,ArmourSkills!$A$2:$A$630,Picker!$B$41,ArmourSkills!$C$2:$C$630,$A5)+SUMIFS(ArmourSkills!$D$2:$D$630,ArmourSkills!$A$2:$A$630,Picker!$B$42,ArmourSkills!$C$2:$C$630,$A5) | C5: =IF($B5=0,"",COUNTIF($B$2:$B$132,">"&$B5)+COUNTIF($B$2:$B5,$B5))
A6: Advanced Thunder Attack | B6: =SUMIFS(ArmourSkills!$D$2:$D$630,ArmourSkills!$A$2:$A$630,Picker!$B$38,ArmourSkills!$C$2:$C$630,$A6)+SUMIFS(ArmourSkills!$D$2:$D$630,ArmourSkills!$A$2:$A$630,Picker!$B$39,ArmourSkills!$C$2:$C$630,$A6)+SUMIFS(ArmourSkills!$D$2:$D$630,ArmourSkills!$A$2:$A$630,Picker!$B$40,ArmourSkills!$C$2:$C$630,$A6)+SUMIFS(ArmourSkills!$D$2:$D$630,ArmourSkills!$A$2:$A$630,Picker!$B$41,ArmourSkills!$C$2:$C$630,$A6)+SUMIFS(ArmourSkills!$D$2:$D$630,ArmourSkills!$A$2:$A$630,Picker!$B$42,ArmourSkills!$C$2:$C$630,$A6) | C6: =IF($B6=0,"",COUNTIF($B$2:$B$132,">"&$B6)+COUNTIF($B$2:$B6,$B6))
A7: Advanced Water Attack | B7: =SUMIFS(ArmourSkills!$D$2:$D$630,ArmourSkills!$A$2:$A$630,Picker!$B$38,ArmourSkills!$C$2:$C$630,$A7)+SUMIFS(ArmourSkills!$D$2:$D$630,ArmourSkills!$A$2:$A$630,Picker!$B$39,ArmourSkills!$C$2:$C$630,$A7)+SUMIFS(ArmourSkills!$D$2:$D$630,ArmourSkills!$A$2:$A$630,Picker!$B$40,ArmourSkills!$C$2:$C$630,$A7)+SUMIFS(ArmourSkills!$D$2:$D$630,ArmourSkills!$A$2:$A$630,Picker!$B$41,ArmourSkills!$C$2:$C$630,$A7)+SUMIFS(ArmourSkills!$D$2:$D$630,ArmourSkills!$A$2:$A$630,Picker!$B$42,ArmourSkills!$C$2:$C$630,$A7) | C7: =IF($B7=0,"",COUNTIF($B$2:$B$132,">"&$B7)+COUNTIF($B$2:$B7,$B7))
A8: Aggressive Dodger | B8: =SUMIFS(ArmourSkills!$D$2:$D$630,ArmourSkills!$A$2:$A$630,Picker!$B$38,ArmourSkills!$C$2:$C$630,$A8)+SUMIFS(ArmourSkills!$D$2:$D$630,ArmourSkills!$A$2:$A$630,Picker!$B$39,ArmourSkills!$C$2:$C$630,$A8)+SUMIFS(ArmourSkills!$D$2:$D$630,ArmourSkills!$A$2:$A$630,Picker!$B$40,ArmourSkills!$C$2:$C$630,$A8)+SUMIFS(ArmourSkills!$D$2:$D$630,ArmourSkills!$A$2:$A$630,Picker!$B$41,ArmourSkills!$C$2:$C$630,$A8)+SUMIFS(ArmourSkills!$D$2:$D$630,ArmourSkills!$A$2:$A$630,Picker!$B$42,ArmourSkills!$C$2:$C$630,$A8) | C8: =IF($B8=0,"",COUNTIF($B$2:$B$132,">"&$B8)+COUNTIF($B$2:$B8,$B8))
A9: Ailment Opportunist | B9: =SUMIFS(ArmourSkills!$D$2:$D$630,ArmourSkills!$A$2:$A$630,Picker!$B$38,ArmourSkills!$C$2:$C$630,$A9)+SUMIFS(ArmourSkills!$D$2:$D$630,ArmourSkills!$A$2:$A$630,Picker!$B$39,ArmourSkills!$C$2:$C$630,$A9)+SUMIFS(ArmourSkills!$D$2:$D$630,ArmourSkills!$A$2:$A$630,Picker!$B$40,ArmourSkills!$C$2:$C$630,$A9)+SUMIFS(ArmourSkills!$D$2:$D$630,ArmourSkills!$A$2:$A$630,Picker!$B$41,ArmourSkills!$C$2:$C$630,$A9)+SUMIFS(ArmourSkills!$D$2:$D$630,ArmourSkills!$A$2:$A$630,Picker!$B$42,ArmourSkills!$C$2:$C$630,$A9) | C9: =IF($B9=0,"",COUNTIF($B$2:$B$132,">"&$B9)+COUNTIF($B$2:$B9,$B9))
A10: Artful Dodger | B10: =SUMIFS(ArmourSkills!$D$2:$D$630,ArmourSkills!$A$2:$A$630,Picker!$B$38,ArmourSkills!$C$2:$C$630,$A10)+SUMIFS(ArmourSkills!$D$2:$D$630,ArmourSkills!$A$2:$A$630,Picker!$B$39,ArmourSkills!$C$2:$C$630,$A10)+SUMIFS(ArmourSkills!$D$2:$D$630,ArmourSkills!$A$2:$A$630,Picker!$B$40,ArmourSkills!$C$2:$C$630,$A10)+SUMIFS(ArmourSkills!$D$2:$D$630,ArmourSkills!$A$2:$A$630,Picker!$B$41,ArmourSkills!$C$2:$C$630,$A10)+SUMIFS(ArmourSkills!$D$2:$D$630,ArmourSkills!$A$2:$A$630,Picker!$B$42,ArmourSkills!$C$2:$C$630,$A10) | C10: =IF($B10=0,"",COUNTIF($B$2:$B$132,">"&$B10)+COUNTIF($B$2:$B10,$B10))
A11: Artillery | B11: =SUMIFS(ArmourSkills!$D$2:$D$630,ArmourSkills!$A$2:$A$630,Picker!$B$38,ArmourSkills!$C$2:$C$630,$A11)+SUMIFS(ArmourSkills!$D$2:$D$630,ArmourSkills!$A$2:$A$630,Picker!$B$39,ArmourSkills!$C$2:$C$630,$A11)+SUMIFS(ArmourSkills!$D$2:$D$630,ArmourSkills!$A$2:$A$630,Picker!$B$40,ArmourSkills!$C$2:$C$630,$A11)+SUMIFS(ArmourSkills!$D$2:$D$630,ArmourSkills!$A$2:$A$630,Picker!$B$41,ArmourSkills!$C$2:$C$630,$A11)+SUMIFS(ArmourSkills!$D$2:$D$630,ArmourSkills!$A$2:$A$630,Picker!$B$42,ArmourSkills!$C$2:$C$630,$A11) | C11: =IF($B11=0,"",COUNTIF($B$2:$B$132,">"&$B11)+COUNTIF($B$2:$B11,$B11))
A12: Attack Boost | B12: =SUMIFS(ArmourSkills!$D$2:$D$630,ArmourSkills!$A$2:$A$630,Picker!$B$38,ArmourSkills!$C$2:$C$630,$A12)+SUMIFS(ArmourSkills!$D$2:$D$630,ArmourSkills!$A$2:$A$630,Picker!$B$39,ArmourSkills!$C$2:$C$630,$A12)+SUMIFS(ArmourSkills!$D$2:$D$630,ArmourSkills!$A$2:$A$630,Picker!$B$40,ArmourSkills!$C$2:$C$630,$A12)+SUMIFS(ArmourSkills!$D$2:$D$630,ArmourSkills!$A$2:$A$630,Picker!$B$41,ArmourSkills!$C$2:$C$630,$A12)+SUMIFS(ArmourSkills!$D$2:$D$630,ArmourSkills!$A$2:$A$630,Picker!$B$42,ArmourSkills!$C$2:$C$630,$A12) | C12: =IF($B12=0,"",COUNTIF($B$2:$B$132,">"&$B12)+COUNTIF($B$2:$B12,$B12))
A13: Attack Efficacy | B13: =SUMIFS(ArmourSkills!$D$2:$D$630,ArmourSkills!$A$2:$A$630,Picker!$B$38,ArmourSkills!$C$2:$C$630,$A13)+SUMIFS(ArmourSkills!$D$2:$D$630,ArmourSkills!$A$2:$A$630,Picker!$B$39,ArmourSkills!$C$2:$C$630,$A13)+SUMIFS(ArmourSkills!$D$2:$D$630,ArmourSkills!$A$2:$A$630,Picker!$B$40,ArmourSkills!$C$2:$C$630,$A13)+SUMIFS(ArmourSkills!$D$2:$D$630,ArmourSkills!$A$2:$A$630,Picker!$B$41,ArmourSkills!$C$2:$C$630,$A13)+SUMIFS(ArmourSkills!$D$2:$D$630,ArmourSkills!$A$2:$A$630,Picker!$B$42,ArmourSkills!$C$2:$C$630,$A13) | C13: =IF($B13=0,"",COUNTIF($B$2:$B$132,">"&$B13)+COUNTIF($B$2:$B13,$B13))
... A132: Windproof | B132: =SUMIFS(ArmourSkills!$D$2:$D$630,ArmourSkills!$A$2:$A$630,Picker!$B$38,ArmourSkills!$C$2:$C$630,$A132)+SUMIFS(ArmourSkills!$D$2:$D$630,ArmourSkills!$A$2:$A$630,Picker!$B$39,ArmourSkills!$C$2:$C$630,$A132)+SUMIFS(ArmourSkills!$D$2:$D$630,ArmourSkills!$A$2:$A$630,Picker!$B$40,ArmourSkills!$C$2:$C$630,$A132)+SUMIFS(ArmourSkills!$D$2:$D$630,ArmourSkills!$A$2:$A$630,Picker!$B$41,ArmourSkills!$C$2:$C$630,$A132)+SUMIFS(ArmourSkills!$D$2:$D$630,ArmourSkills!$A$2:$A$630,Picker!$B$42,ArmourSkills!$C$2:$C$630,$A132) | C132: =IF($B132=0,"",COUNTIF($B$2:$B$132,">"&$B132)+COUNTIF($B$2:$B132,$B132))
